Internal Server Error: /
Traceback (most recent call last):
  File "C:\Users\User\AppData\Roaming\Python\Python313\site-packages\asgiref\local.py", line 89, in _lock_storage
    asyncio.get_running_loop()
    ~~~~~~~~~~~~~~~~~~~~~~~~^^
RuntimeError: no running event loop

During handling of the above exception, another exception occurred:

Traceback (most recent call last):
  File "C:\Users\User\AppData\Roaming\Python\Python313\site-packages\django\utils\connection.py", line 58, in __getitem__
    return getattr(self._connections, alias)
  File "C:\Users\User\AppData\Roaming\Python\Python313\site-packages\asgiref\local.py", line 118, in __getattr__
    return getattr(storage, key)
AttributeError: '_thread._local' object has no attribute 'second_db'

During handling of the above exception, another exception occurred:

Traceback (most recent call last):
  File "C:\Users\User\AppData\Roaming\Python\Python313\site-packages\django\core\handlers\exception.py", line 55, in inner
    response = get_response(request)
  File "C:\Users\User\AppData\Roaming\Python\Python313\site-packages\django\core\handlers\base.py", line 197, in _get_response
    response = wrapped_callback(request, *callback_args, **callback_kwargs)
  File "C:\Users\User\Desktop\New folder (3)\Cyber-Security-Awareness-Quiz\Sonata_Cyber_Quiz\Quiz\views.py", line 48, in home
    with connections['second_db'].cursor() as cursor:
         ~~~~~~~~~~~^^^^^^^^^^^^^
  File "C:\Users\User\AppData\Roaming\Python\Python313\site-packages\django\utils\connection.py", line 61, in __getitem__
    raise self.exception_class(f"The connection '{alias}' doesn't exist.")
django.utils.connection.ConnectionDoesNotExist: The connection 'second_db' doesn't exist.
"POST / HTTP/1.1" 500 1427
Internal Server Error: /
Traceback (most recent call last):
  File "C:\Users\User\AppData\Roaming\Python\Python313\site-packages\asgiref\local.py", line 89, in _lock_storage
    asyncio.get_running_loop()
    ~~~~~~~~~~~~~~~~~~~~~~~~^^
RuntimeError: no running event loop

During handling of the above exception, another exception occurred:

Traceback (most recent call last):
  File "C:\Users\User\AppData\Roaming\Python\Python313\site-packages\django\utils\connection.py", line 58, in __getitem__
    return getattr(self._connections, alias)
  File "C:\Users\User\AppData\Roaming\Python\Python313\site-packages\asgiref\local.py", line 118, in __getattr__
    return getattr(storage, key)
AttributeError: '_thread._local' object has no attribute 'second_db'

During handling of the above exception, another exception occurred:

Traceback (most recent call last):
  File "C:\Users\User\AppData\Roaming\Python\Python313\site-packages\django\core\handlers\exception.py", line 55, in inner
    response = get_response(request)
  File "C:\Users\User\AppData\Roaming\Python\Python313\site-packages\django\core\handlers\base.py", line 197, in _get_response
    response = wrapped_callback(request, *callback_args, **callback_kwargs)
  File "C:\Users\User\Desktop\New folder (3)\Cyber-Security-Awareness-Quiz\Sonata_Cyber_Quiz\Quiz\views.py", line 48, in home
    with connections['second_db'].cursor() as cursor:
         ~~~~~~~~~~~^^^^^^^^^^^^^
  File "C:\Users\User\AppData\Roaming\Python\Python313\site-packages\django\utils\connection.py", line 61, in __getitem__
    raise self.exception_class(f"The connection '{alias}' doesn't exist.")
django.utils.connection.ConnectionDoesNotExist: The connection 'second_db' doesn't exist.
"POST / HTTP/1.1" 500 1427
Internal Server Error: /get-emp-images/
Traceback (most recent call last):
  File "C:\Users\User\AppData\Roaming\Python\Python313\site-packages\django\core\handlers\exception.py", line 55, in inner
    response = get_response(request)
  File "C:\Users\User\AppData\Roaming\Python\Python313\site-packages\django\core\handlers\base.py", line 197, in _get_response
    response = wrapped_callback(request, *callback_args, **callback_kwargs)
  File "C:\Users\User\Desktop\New folder (3)\Cyber-Security-Awareness-Quiz\Sonata_Cyber_Quiz\Quiz\views.py", line 137, in get_emp_images
    emp = SonataUsersKYCData.objects.get(EmpID=emp_id, IsProcessed=0,IsActive = 1)
  File "C:\Users\User\AppData\Roaming\Python\Python313\site-packages\django\db\models\manager.py", line 87, in manager_method
    return getattr(self.get_queryset(), name)(*args, **kwargs)
           ~~~~~~~~~~~~~~~~~~~~~~~~~~~~~~~~~~^^^^^^^^^^^^^^^^^
  File "C:\Users\User\AppData\Roaming\Python\Python313\site-packages\django\db\models\query.py", line 652, in get
    raise self.model.MultipleObjectsReturned(
    ...<5 lines>...
    )
Quiz.models.SonataUsersKYCData.MultipleObjectsReturned: get() returned more than one SonataUsersKYCData -- it returned 2!
"GET /get-emp-images/?empid=18203 HTTP/1.1" 500 1427
Internal Server Error: /get-emp-images/
Traceback (most recent call last):
  File "C:\Users\User\AppData\Roaming\Python\Python313\site-packages\django\core\handlers\exception.py", line 55, in inner
    response = get_response(request)
  File "C:\Users\User\AppData\Roaming\Python\Python313\site-packages\django\core\handlers\base.py", line 197, in _get_response
    response = wrapped_callback(request, *callback_args, **callback_kwargs)
  File "C:\Users\User\Desktop\New folder (3)\Cyber-Security-Awareness-Quiz\Sonata_Cyber_Quiz\Quiz\views.py", line 137, in get_emp_images
    emp = SonataUsersKYCData.objects.get(EmpID=emp_id, IsProcessed=0,IsActive = 1)
  File "C:\Users\User\AppData\Roaming\Python\Python313\site-packages\django\db\models\manager.py", line 87, in manager_method
    return getattr(self.get_queryset(), name)(*args, **kwargs)
           ~~~~~~~~~~~~~~~~~~~~~~~~~~~~~~~~~~^^^^^^^^^^^^^^^^^
  File "C:\Users\User\AppData\Roaming\Python\Python313\site-packages\django\db\models\query.py", line 652, in get
    raise self.model.MultipleObjectsReturned(
    ...<5 lines>...
    )
Quiz.models.SonataUsersKYCData.MultipleObjectsReturned: get() returned more than one SonataUsersKYCData -- it returned 2!
"GET /get-emp-images/?empid=18203 HTTP/1.1" 500 1427
Internal Server Error: /get-emp-images/
Traceback (most recent call last):
  File "C:\Users\User\AppData\Roaming\Python\Python313\site-packages\django\core\handlers\exception.py", line 55, in inner
    response = get_response(request)
  File "C:\Users\User\AppData\Roaming\Python\Python313\site-packages\django\core\handlers\base.py", line 197, in _get_response
    response = wrapped_callback(request, *callback_args, **callback_kwargs)
  File "C:\Users\User\Desktop\New folder (3)\Cyber-Security-Awareness-Quiz\Sonata_Cyber_Quiz\Quiz\views.py", line 137, in get_emp_images
    emp = SonataUsersKYCData.objects.get(EmpID=emp_id, IsProcessed=0,IsActive = 1)
  File "C:\Users\User\AppData\Roaming\Python\Python313\site-packages\django\db\models\manager.py", line 87, in manager_method
    return getattr(self.get_queryset(), name)(*args, **kwargs)
           ~~~~~~~~~~~~~~~~~~~~~~~~~~~~~~~~~~^^^^^^^^^^^^^^^^^
  File "C:\Users\User\AppData\Roaming\Python\Python313\site-packages\django\db\models\query.py", line 652, in get
    raise self.model.MultipleObjectsReturned(
    ...<5 lines>...
    )
Quiz.models.SonataUsersKYCData.MultipleObjectsReturned: get() returned more than one SonataUsersKYCData -- it returned 2!
"GET /get-emp-images/?empid=18203 HTTP/1.1" 500 1427
Internal Server Error: /get-emp-images/
Traceback (most recent call last):
  File "C:\Users\User\AppData\Roaming\Python\Python313\site-packages\django\core\handlers\exception.py", line 55, in inner
    response = get_response(request)
  File "C:\Users\User\AppData\Roaming\Python\Python313\site-packages\django\core\handlers\base.py", line 197, in _get_response
    response = wrapped_callback(request, *callback_args, **callback_kwargs)
  File "C:\Users\User\Desktop\New folder (3)\Cyber-Security-Awareness-Quiz\Sonata_Cyber_Quiz\Quiz\views.py", line 137, in get_emp_images
    emp = SonataUsersKYCData.objects.get(EmpID=emp_id, IsProcessed=0,IsActive = 1)
  File "C:\Users\User\AppData\Roaming\Python\Python313\site-packages\django\db\models\manager.py", line 87, in manager_method
    return getattr(self.get_queryset(), name)(*args, **kwargs)
           ~~~~~~~~~~~~~~~~~~~~~~~~~~~~~~~~~~^^^^^^^^^^^^^^^^^
  File "C:\Users\User\AppData\Roaming\Python\Python313\site-packages\django\db\models\query.py", line 652, in get
    raise self.model.MultipleObjectsReturned(
    ...<5 lines>...
    )
Quiz.models.SonataUsersKYCData.MultipleObjectsReturned: get() returned more than one SonataUsersKYCData -- it returned 2!
"GET /get-emp-images/?empid=18203 HTTP/1.1" 500 1427
Internal Server Error: /get-emp-images/
Traceback (most recent call last):
  File "C:\Users\User\AppData\Roaming\Python\Python313\site-packages\django\core\handlers\exception.py", line 55, in inner
    response = get_response(request)
  File "C:\Users\User\AppData\Roaming\Python\Python313\site-packages\django\core\handlers\base.py", line 197, in _get_response
    response = wrapped_callback(request, *callback_args, **callback_kwargs)
  File "C:\Users\User\Desktop\New folder (3)\Cyber-Security-Awareness-Quiz\Sonata_Cyber_Quiz\Quiz\views.py", line 137, in get_emp_images
    emp = SonataUsersKYCData.objects.get(EmpID=emp_id, IsProcessed=0,IsActive = 1)
  File "C:\Users\User\AppData\Roaming\Python\Python313\site-packages\django\db\models\manager.py", line 87, in manager_method
    return getattr(self.get_queryset(), name)(*args, **kwargs)
           ~~~~~~~~~~~~~~~~~~~~~~~~~~~~~~~~~~^^^^^^^^^^^^^^^^^
  File "C:\Users\User\AppData\Roaming\Python\Python313\site-packages\django\db\models\query.py", line 652, in get
    raise self.model.MultipleObjectsReturned(
    ...<5 lines>...
    )
Quiz.models.SonataUsersKYCData.MultipleObjectsReturned: get() returned more than one SonataUsersKYCData -- it returned 2!
"GET /get-emp-images/?empid=18203 HTTP/1.1" 500 1427
Internal Server Error: /download-reports/
"GET /download-reports/?type=completed&start=2025-03-20&end=2025-03-22 HTTP/1.1" 500 232
Internal Server Error: /download-reports/
"GET /download-reports/?type=completed&start=2025-03-20&end=2025-03-22 HTTP/1.1" 500 232
Internal Server Error: /download-reports/
"GET /download-reports/?type=completed&start=2025-03-20&end=2025-03-22 HTTP/1.1" 500 232
Internal Server Error: /download-reports/
"GET /download-reports/?type=completed&start=2025-03-20&end=2025-03-22 HTTP/1.1" 500 232
Internal Server Error: /download-reports/
"GET /download-reports/?type=completed&start=2025-03-20&end=2025-03-22 HTTP/1.1" 500 232
Internal Server Error: /download-reports/
Traceback (most recent call last):
  File "C:\Users\hp\AppData\Local\Programs\Python\Python311\Lib\site-packages\django\contrib\sessions\backends\base.py", line 233, in _get_session
    return self._session_cache
           ^^^^^^^^^^^^^^^^^^^
AttributeError: 'SessionStore' object has no attribute '_session_cache'

During handling of the above exception, another exception occurred:

Traceback (most recent call last):
  File "C:\Users\hp\AppData\Local\Programs\Python\Python311\Lib\site-packages\django\db\backends\base\base.py", line 219, in ensure_connection
    self.connect()
  File "C:\Users\hp\AppData\Local\Programs\Python\Python311\Lib\site-packages\django\utils\asyncio.py", line 33, in inner
    return func(*args, **kwargs)
           ^^^^^^^^^^^^^^^^^^^^^
  File "C:\Users\hp\AppData\Local\Programs\Python\Python311\Lib\site-packages\django\db\backends\base\base.py", line 200, in connect
    self.connection = self.get_new_connection(conn_params)
                      ^^^^^^^^^^^^^^^^^^^^^^^^^^^^^^^^^^^^
  File "C:\Users\hp\AppData\Local\Programs\Python\Python311\Lib\site-packages\mssql\base.py", line 368, in get_new_connection
    conn = Database.connect(connstr, **args)
           ^^^^^^^^^^^^^^^^^^^^^^^^^^^^^^^^^
pyodbc.OperationalError: ('08S01', '[08S01] [Microsoft][ODBC Driver 17 for SQL Server]TCP Provider: An existing connection was forcibly closed by the remote host.\r\n (10054) (SQLSetConnectAttr(SQL_ATTR_AUTOCOMMIT)); [08S01] [Microsoft][ODBC Driver 17 for SQL Server]TCP Provider: An existing connection was forcibly closed by the remote host.\r\n (10054); [08S01] [Microsoft][ODBC Driver 17 for SQL Server]Communication link failure (10054); [08S01] [Microsoft][ODBC Driver 17 for SQL Server]Communication link failure (10054)')

The above exception was the direct cause of the following exception:

Traceback (most recent call last):
  File "C:\Users\hp\AppData\Local\Programs\Python\Python311\Lib\site-packages\django\core\handlers\exception.py", line 47, in inner
    response = get_response(request)
               ^^^^^^^^^^^^^^^^^^^^^
  File "C:\Users\hp\AppData\Local\Programs\Python\Python311\Lib\site-packages\django\core\handlers\base.py", line 181, in _get_response
    response = wrapped_callback(request, *callback_args, **callback_kwargs)
               ^^^^^^^^^^^^^^^^^^^^^^^^^^^^^^^^^^^^^^^^^^^^^^^^^^^^^^^^^^^^
  File "C:\Users\hp\Downloads\Cyber-Security-Awareness-Quiz (2)\Cyber-Security-Awareness-Quiz\Cyber-Security-Awareness-Quiz\Sonata_Cyber_Quiz\Quiz\views.py", line 275, in download_reports
    if 'employee_id' not in request.session:
       ^^^^^^^^^^^^^^^^^^^^^^^^^^^^^^^^^^^^
  File "C:\Users\hp\AppData\Local\Programs\Python\Python311\Lib\site-packages\django\contrib\sessions\backends\base.py", line 55, in __contains__
    return key in self._session
                  ^^^^^^^^^^^^^
  File "C:\Users\hp\AppData\Local\Programs\Python\Python311\Lib\site-packages\django\contrib\sessions\backends\base.py", line 238, in _get_session
    self._session_cache = self.load()
                          ^^^^^^^^^^^
  File "C:\Users\hp\AppData\Local\Programs\Python\Python311\Lib\site-packages\django\contrib\sessions\backends\db.py", line 43, in load
    s = self._get_session_from_db()
        ^^^^^^^^^^^^^^^^^^^^^^^^^^^
  File "C:\Users\hp\AppData\Local\Programs\Python\Python311\Lib\site-packages\django\contrib\sessions\backends\db.py", line 32, in _get_session_from_db
    return self.model.objects.get(
           ^^^^^^^^^^^^^^^^^^^^^^^
  File "C:\Users\hp\AppData\Local\Programs\Python\Python311\Lib\site-packages\django\db\models\manager.py", line 85, in manager_method
    return getattr(self.get_queryset(), name)(*args, **kwargs)
           ^^^^^^^^^^^^^^^^^^^^^^^^^^^^^^^^^^^^^^^^^^^^^^^^^^^
  File "C:\Users\hp\AppData\Local\Programs\Python\Python311\Lib\site-packages\django\db\models\query.py", line 431, in get
    num = len(clone)
          ^^^^^^^^^^
  File "C:\Users\hp\AppData\Local\Programs\Python\Python311\Lib\site-packages\django\db\models\query.py", line 262, in __len__
    self._fetch_all()
  File "C:\Users\hp\AppData\Local\Programs\Python\Python311\Lib\site-packages\django\db\models\query.py", line 1324, in _fetch_all
    self._result_cache = list(self._iterable_class(self))
                         ^^^^^^^^^^^^^^^^^^^^^^^^^^^^^^^^
  File "C:\Users\hp\AppData\Local\Programs\Python\Python311\Lib\site-packages\django\db\models\query.py", line 51, in __iter__
    results = compiler.execute_sql(chunked_fetch=self.chunked_fetch, chunk_size=self.chunk_size)
              ^^^^^^^^^^^^^^^^^^^^^^^^^^^^^^^^^^^^^^^^^^^^^^^^^^^^^^^^^^^^^^^^^^^^^^^^^^^^^^^^^^
  File "C:\Users\hp\AppData\Local\Programs\Python\Python311\Lib\site-packages\django\db\models\sql\compiler.py", line 1173, in execute_sql
    cursor = self.connection.cursor()
             ^^^^^^^^^^^^^^^^^^^^^^^^
  File "C:\Users\hp\AppData\Local\Programs\Python\Python311\Lib\site-packages\django\utils\asyncio.py", line 33, in inner
    return func(*args, **kwargs)
           ^^^^^^^^^^^^^^^^^^^^^
  File "C:\Users\hp\AppData\Local\Programs\Python\Python311\Lib\site-packages\django\db\backends\base\base.py", line 259, in cursor
    return self._cursor()
           ^^^^^^^^^^^^^^
  File "C:\Users\hp\AppData\Local\Programs\Python\Python311\Lib\site-packages\mssql\base.py", line 261, in _cursor
    conn = super()._cursor()
           ^^^^^^^^^^^^^^^^^
  File "C:\Users\hp\AppData\Local\Programs\Python\Python311\Lib\site-packages\django\db\backends\base\base.py", line 235, in _cursor
    self.ensure_connection()
  File "C:\Users\hp\AppData\Local\Programs\Python\Python311\Lib\site-packages\django\utils\asyncio.py", line 33, in inner
    return func(*args, **kwargs)
           ^^^^^^^^^^^^^^^^^^^^^
  File "C:\Users\hp\AppData\Local\Programs\Python\Python311\Lib\site-packages\django\db\backends\base\base.py", line 218, in ensure_connection
    with self.wrap_database_errors:
  File "C:\Users\hp\AppData\Local\Programs\Python\Python311\Lib\site-packages\django\db\utils.py", line 90, in __exit__
    raise dj_exc_value.with_traceback(traceback) from exc_value
  File "C:\Users\hp\AppData\Local\Programs\Python\Python311\Lib\site-packages\django\db\backends\base\base.py", line 219, in ensure_connection
    self.connect()
  File "C:\Users\hp\AppData\Local\Programs\Python\Python311\Lib\site-packages\django\utils\asyncio.py", line 33, in inner
    return func(*args, **kwargs)
           ^^^^^^^^^^^^^^^^^^^^^
  File "C:\Users\hp\AppData\Local\Programs\Python\Python311\Lib\site-packages\django\db\backends\base\base.py", line 200, in connect
    self.connection = self.get_new_connection(conn_params)
                      ^^^^^^^^^^^^^^^^^^^^^^^^^^^^^^^^^^^^
  File "C:\Users\hp\AppData\Local\Programs\Python\Python311\Lib\site-packages\mssql\base.py", line 368, in get_new_connection
    conn = Database.connect(connstr, **args)
           ^^^^^^^^^^^^^^^^^^^^^^^^^^^^^^^^^
django.db.utils.OperationalError: ('08S01', '[08S01] [Microsoft][ODBC Driver 17 for SQL Server]TCP Provider: An existing connection was forcibly closed by the remote host.\r\n (10054) (SQLSetConnectAttr(SQL_ATTR_AUTOCOMMIT)); [08S01] [Microsoft][ODBC Driver 17 for SQL Server]TCP Provider: An existing connection was forcibly closed by the remote host.\r\n (10054); [08S01] [Microsoft][ODBC Driver 17 for SQL Server]Communication link failure (10054); [08S01] [Microsoft][ODBC Driver 17 for SQL Server]Communication link failure (10054)')
"GET /download-reports/?type=completed&start=2025-03-20&end=2025-03-22 HTTP/1.1" 500 1427
Internal Server Error: /download-reports/
"GET /download-reports/?type=completed&start=2025-03-19&end=2025-03-22 HTTP/1.1" 500 135
Internal Server Error: /download-reports/
"GET /download-reports/?type=completed&start=2025-03-19&end=2025-03-21 HTTP/1.1" 500 159
Internal Server Error: /HR_dashboard/
Traceback (most recent call last):
  File "C:\Users\User\AppData\Roaming\Python\Python313\site-packages\django\db\backends\utils.py", line 103, in _execute
    return self.cursor.execute(sql)
           ~~~~~~~~~~~~~~~~~~~^^^^^
  File "C:\Users\User\AppData\Roaming\Python\Python313\site-packages\mssql\base.py", line 677, in execute
    return self.cursor.execute(sql, params)
           ~~~~~~~~~~~~~~~~~~~^^^^^^^^^^^^^
pyodbc.ProgrammingError: ('42000', "[42000] [Microsoft][ODBC Driver 17 for SQL Server][SQL Server]Incorrect syntax near the keyword 'FROM'. (156) (SQLExecDirectW)")

The above exception was the direct cause of the following exception:

Traceback (most recent call last):
  File "C:\Users\User\AppData\Roaming\Python\Python313\site-packages\django\core\handlers\exception.py", line 55, in inner
    response = get_response(request)
  File "C:\Users\User\AppData\Roaming\Python\Python313\site-packages\django\core\handlers\base.py", line 197, in _get_response
    response = wrapped_callback(request, *callback_args, **callback_kwargs)
  File "C:\Users\User\Downloads\Cyber-Security-Awareness-Quiz\Cyber-Security-Awareness-Quiz\Sonata_Cyber_Quiz\Quiz\views.py", line 179, in HR_dashboard
    cursor.execute(query)
    ~~~~~~~~~~~~~~^^^^^^^
  File "C:\Users\User\AppData\Roaming\Python\Python313\site-packages\django\db\backends\utils.py", line 79, in execute
    return self._execute_with_wrappers(
           ~~~~~~~~~~~~~~~~~~~~~~~~~~~^
        sql, params, many=False, executor=self._execute
        ^^^^^^^^^^^^^^^^^^^^^^^^^^^^^^^^^^^^^^^^^^^^^^^
    )
    ^
  File "C:\Users\User\AppData\Roaming\Python\Python313\site-packages\django\db\backends\utils.py", line 92, in _execute_with_wrappers
    return executor(sql, params, many, context)
  File "C:\Users\User\AppData\Roaming\Python\Python313\site-packages\django\db\backends\utils.py", line 100, in _execute
    with self.db.wrap_database_errors:
         ^^^^^^^^^^^^^^^^^^^^^^^^^^^^
  File "C:\Users\User\AppData\Roaming\Python\Python313\site-packages\django\db\utils.py", line 91, in __exit__
    raise dj_exc_value.with_traceback(traceback) from exc_value
  File "C:\Users\User\AppData\Roaming\Python\Python313\site-packages\django\db\backends\utils.py", line 103, in _execute
    return self.cursor.execute(sql)
           ~~~~~~~~~~~~~~~~~~~^^^^^
  File "C:\Users\User\AppData\Roaming\Python\Python313\site-packages\mssql\base.py", line 677, in execute
    return self.cursor.execute(sql, params)
           ~~~~~~~~~~~~~~~~~~~^^^^^^^^^^^^^
django.db.utils.ProgrammingError: ('42000', "[42000] [Microsoft][ODBC Driver 17 for SQL Server][SQL Server]Incorrect syntax near the keyword 'FROM'. (156) (SQLExecDirectW)")
"GET /HR_dashboard/ HTTP/1.1" 500 1427
Internal Server Error: /HR_dashboard/
Traceback (most recent call last):
  File "C:\Users\User\AppData\Roaming\Python\Python313\site-packages\django\db\backends\utils.py", line 103, in _execute
    return self.cursor.execute(sql)
           ~~~~~~~~~~~~~~~~~~~^^^^^
  File "C:\Users\User\AppData\Roaming\Python\Python313\site-packages\mssql\base.py", line 677, in execute
    return self.cursor.execute(sql, params)
           ~~~~~~~~~~~~~~~~~~~^^^^^^^^^^^^^
pyodbc.ProgrammingError: ('42000', "[42000] [Microsoft][ODBC Driver 17 for SQL Server][SQL Server]Incorrect syntax near the keyword 'FROM'. (156) (SQLExecDirectW)")

The above exception was the direct cause of the following exception:

Traceback (most recent call last):
  File "C:\Users\User\AppData\Roaming\Python\Python313\site-packages\django\core\handlers\exception.py", line 55, in inner
    response = get_response(request)
  File "C:\Users\User\AppData\Roaming\Python\Python313\site-packages\django\core\handlers\base.py", line 197, in _get_response
    response = wrapped_callback(request, *callback_args, **callback_kwargs)
  File "C:\Users\User\Downloads\Cyber-Security-Awareness-Quiz\Cyber-Security-Awareness-Quiz\Sonata_Cyber_Quiz\Quiz\views.py", line 179, in HR_dashboard
    cursor.execute(query)
    ~~~~~~~~~~~~~~^^^^^^^
  File "C:\Users\User\AppData\Roaming\Python\Python313\site-packages\django\db\backends\utils.py", line 79, in execute
    return self._execute_with_wrappers(
           ~~~~~~~~~~~~~~~~~~~~~~~~~~~^
        sql, params, many=False, executor=self._execute
        ^^^^^^^^^^^^^^^^^^^^^^^^^^^^^^^^^^^^^^^^^^^^^^^
    )
    ^
  File "C:\Users\User\AppData\Roaming\Python\Python313\site-packages\django\db\backends\utils.py", line 92, in _execute_with_wrappers
    return executor(sql, params, many, context)
  File "C:\Users\User\AppData\Roaming\Python\Python313\site-packages\django\db\backends\utils.py", line 100, in _execute
    with self.db.wrap_database_errors:
         ^^^^^^^^^^^^^^^^^^^^^^^^^^^^
  File "C:\Users\User\AppData\Roaming\Python\Python313\site-packages\django\db\utils.py", line 91, in __exit__
    raise dj_exc_value.with_traceback(traceback) from exc_value
  File "C:\Users\User\AppData\Roaming\Python\Python313\site-packages\django\db\backends\utils.py", line 103, in _execute
    return self.cursor.execute(sql)
           ~~~~~~~~~~~~~~~~~~~^^^^^
  File "C:\Users\User\AppData\Roaming\Python\Python313\site-packages\mssql\base.py", line 677, in execute
    return self.cursor.execute(sql, params)
           ~~~~~~~~~~~~~~~~~~~^^^^^^^^^^^^^
django.db.utils.ProgrammingError: ('42000', "[42000] [Microsoft][ODBC Driver 17 for SQL Server][SQL Server]Incorrect syntax near the keyword 'FROM'. (156) (SQLExecDirectW)")
"GET /HR_dashboard/ HTTP/1.1" 500 1427
Internal Server Error: /HR_dashboard/
Traceback (most recent call last):
  File "C:\Users\User\AppData\Roaming\Python\Python313\site-packages\django\db\backends\utils.py", line 103, in _execute
    return self.cursor.execute(sql)
           ~~~~~~~~~~~~~~~~~~~^^^^^
  File "C:\Users\User\AppData\Roaming\Python\Python313\site-packages\mssql\base.py", line 677, in execute
    return self.cursor.execute(sql, params)
           ~~~~~~~~~~~~~~~~~~~^^^^^^^^^^^^^
pyodbc.ProgrammingError: ('42000', "[42000] [Microsoft][ODBC Driver 17 for SQL Server][SQL Server]Incorrect syntax near the keyword 'FROM'. (156) (SQLExecDirectW)")

The above exception was the direct cause of the following exception:

Traceback (most recent call last):
  File "C:\Users\User\AppData\Roaming\Python\Python313\site-packages\django\core\handlers\exception.py", line 55, in inner
    response = get_response(request)
  File "C:\Users\User\AppData\Roaming\Python\Python313\site-packages\django\core\handlers\base.py", line 197, in _get_response
    response = wrapped_callback(request, *callback_args, **callback_kwargs)
  File "C:\Users\User\Downloads\Cyber-Security-Awareness-Quiz\Cyber-Security-Awareness-Quiz\Sonata_Cyber_Quiz\Quiz\views.py", line 179, in HR_dashboard
    cursor.execute(query)
    ~~~~~~~~~~~~~~^^^^^^^
  File "C:\Users\User\AppData\Roaming\Python\Python313\site-packages\django\db\backends\utils.py", line 79, in execute
    return self._execute_with_wrappers(
           ~~~~~~~~~~~~~~~~~~~~~~~~~~~^
        sql, params, many=False, executor=self._execute
        ^^^^^^^^^^^^^^^^^^^^^^^^^^^^^^^^^^^^^^^^^^^^^^^
    )
    ^
  File "C:\Users\User\AppData\Roaming\Python\Python313\site-packages\django\db\backends\utils.py", line 92, in _execute_with_wrappers
    return executor(sql, params, many, context)
  File "C:\Users\User\AppData\Roaming\Python\Python313\site-packages\django\db\backends\utils.py", line 100, in _execute
    with self.db.wrap_database_errors:
         ^^^^^^^^^^^^^^^^^^^^^^^^^^^^
  File "C:\Users\User\AppData\Roaming\Python\Python313\site-packages\django\db\utils.py", line 91, in __exit__
    raise dj_exc_value.with_traceback(traceback) from exc_value
  File "C:\Users\User\AppData\Roaming\Python\Python313\site-packages\django\db\backends\utils.py", line 103, in _execute
    return self.cursor.execute(sql)
           ~~~~~~~~~~~~~~~~~~~^^^^^
  File "C:\Users\User\AppData\Roaming\Python\Python313\site-packages\mssql\base.py", line 677, in execute
    return self.cursor.execute(sql, params)
           ~~~~~~~~~~~~~~~~~~~^^^^^^^^^^^^^
django.db.utils.ProgrammingError: ('42000', "[42000] [Microsoft][ODBC Driver 17 for SQL Server][SQL Server]Incorrect syntax near the keyword 'FROM'. (156) (SQLExecDirectW)")
"GET /HR_dashboard/ HTTP/1.1" 500 1427
Internal Server Error: /verify-document/
"POST /verify-document/ HTTP/1.1" 500 107
Internal Server Error: /verify-document/
"POST /verify-document/ HTTP/1.1" 500 271
Internal Server Error: /verify-document/
"POST /verify-document/ HTTP/1.1" 500 271
Internal Server Error: /verify-document/
"POST /verify-document/ HTTP/1.1" 500 273
Internal Server Error: /verify-document/
"POST /verify-document/ HTTP/1.1" 500 273
Internal Server Error: /verify-document/
"POST /verify-document/ HTTP/1.1" 500 273
Internal Server Error: /verify-document/
"POST /verify-document/ HTTP/1.1" 500 273
Internal Server Error: /verify-document/
"POST /verify-document/ HTTP/1.1" 500 273
Internal Server Error: /verify-document/
"POST /verify-document/ HTTP/1.1" 500 273
Internal Server Error: /verify-document/
"POST /verify-document/ HTTP/1.1" 500 273
Internal Server Error: /verify-document/
"POST /verify-document/ HTTP/1.1" 500 273
Internal Server Error: /verify-document/
"POST /verify-document/ HTTP/1.1" 500 273
Internal Server Error: /final-submission/
"POST /final-submission/ HTTP/1.1" 500 77
Internal Server Error: /final-submission/
"POST /final-submission/ HTTP/1.1" 500 77
Internal Server Error: /employee_kyc_view/
Traceback (most recent call last):
  File "C:\Users\User\AppData\Roaming\Python\Python313\site-packages\django\core\handlers\exception.py", line 55, in inner
    response = get_response(request)
  File "C:\Users\User\AppData\Roaming\Python\Python313\site-packages\django\core\handlers\base.py", line 197, in _get_response
    response = wrapped_callback(request, *callback_args, **callback_kwargs)
  File "C:\Users\User\Downloads\Cyber-Security-Awareness-Quiz\Cyber-Security-Awareness-Quiz\Sonata_Cyber_Quiz\Quiz\views.py", line 86, in employee_kyc_view
    employees = SonataUsersKYCData.objects.filter(Q(EmpID__icontains=search_query) | Q(MobileNo__icontains=search_query) | Q(AdhaarNo__icontains=search_query) | Q(PAN_Number__icontains=search_query) | Q(DOB_icontains = search_query)) # Search query
  File "C:\Users\User\AppData\Roaming\Python\Python313\site-packages\django\db\models\manager.py", line 87, in manager_method
    return getattr(self.get_queryset(), name)(*args, **kwargs)
           ~~~~~~~~~~~~~~~~~~~~~~~~~~~~~~~~~~^^^^^^^^^^^^^^^^^
  File "C:\Users\User\AppData\Roaming\Python\Python313\site-packages\django\db\models\query.py", line 1476, in filter
    return self._filter_or_exclude(False, args, kwargs)
           ~~~~~~~~~~~~~~~~~~~~~~~^^^^^^^^^^^^^^^^^^^^^
  File "C:\Users\User\AppData\Roaming\Python\Python313\site-packages\django\db\models\query.py", line 1494, in _filter_or_exclude
    clone._filter_or_exclude_inplace(negate, args, kwargs)
    ~~~~~~~~~~~~~~~~~~~~~~~~~~~~~~~~^^^^^^^^^^^^^^^^^^^^^^
  File "C:\Users\User\AppData\Roaming\Python\Python313\site-packages\django\db\models\query.py", line 1501, in _filter_or_exclude_inplace
    self._query.add_q(Q(*args, **kwargs))
    ~~~~~~~~~~~~~~~~~^^^^^^^^^^^^^^^^^^^^
  File "C:\Users\User\AppData\Roaming\Python\Python313\site-packages\django\db\models\sql\query.py", line 1613, in add_q
    clause, _ = self._add_q(q_object, self.used_aliases)
                ~~~~~~~~~~~^^^^^^^^^^^^^^^^^^^^^^^^^^^^^
  File "C:\Users\User\AppData\Roaming\Python\Python313\site-packages\django\db\models\sql\query.py", line 1645, in _add_q
    child_clause, needed_inner = self.build_filter(
                                 ~~~~~~~~~~~~~~~~~^
        child,
        ^^^^^^
    ...<7 lines>...
        update_join_types=update_join_types,
        ^^^^^^^^^^^^^^^^^^^^^^^^^^^^^^^^^^^^
    )
    ^
  File "C:\Users\User\AppData\Roaming\Python\Python313\site-packages\django\db\models\sql\query.py", line 1472, in build_filter
    return self._add_q(
           ~~~~~~~~~~~^
        filter_expr,
        ^^^^^^^^^^^^
    ...<7 lines>...
        update_join_types=update_join_types,
        ^^^^^^^^^^^^^^^^^^^^^^^^^^^^^^^^^^^^
    )
    ^
  File "C:\Users\User\AppData\Roaming\Python\Python313\site-packages\django\db\models\sql\query.py", line 1645, in _add_q
    child_clause, needed_inner = self.build_filter(
                                 ~~~~~~~~~~~~~~~~~^
        child,
        ^^^^^^
    ...<7 lines>...
        update_join_types=update_join_types,
        ^^^^^^^^^^^^^^^^^^^^^^^^^^^^^^^^^^^^
    )
    ^
  File "C:\Users\User\AppData\Roaming\Python\Python313\site-packages\django\db\models\sql\query.py", line 1495, in build_filter
    lookups, parts, reffed_expression = self.solve_lookup_type(arg, summarize)
                                        ~~~~~~~~~~~~~~~~~~~~~~^^^^^^^^^^^^^^^^
  File "C:\Users\User\AppData\Roaming\Python\Python313\site-packages\django\db\models\sql\query.py", line 1307, in solve_lookup_type
    _, field, _, lookup_parts = self.names_to_path(lookup_splitted, self.get_meta())
                                ~~~~~~~~~~~~~~~~~~^^^^^^^^^^^^^^^^^^^^^^^^^^^^^^^^^^
  File "C:\Users\User\AppData\Roaming\Python\Python313\site-packages\django\db\models\sql\query.py", line 1772, in names_to_path
    raise FieldError(
    ...<2 lines>...
    )
django.core.exceptions.FieldError: Cannot resolve keyword 'DOB_icontains' into field. Choices are: AdhaarBackImg, AdhaarFrontImg, AdhaarNo, DL_Img, DOB, EmpID, IsActive, IsProcessed, MobileNo, PAN_Img, PAN_Number, Passbook_Img, Photo, RecievedDate, StageID, id
"GET /employee_kyc_view/?search=7527 HTTP/1.1" 500 1427
Internal Server Error: /employee_kyc_view/
Traceback (most recent call last):
  File "C:\Users\User\AppData\Roaming\Python\Python313\site-packages\django\core\handlers\exception.py", line 55, in inner
    response = get_response(request)
  File "C:\Users\User\AppData\Roaming\Python\Python313\site-packages\django\core\handlers\base.py", line 197, in _get_response
    response = wrapped_callback(request, *callback_args, **callback_kwargs)
  File "C:\Users\User\Downloads\Cyber-Security-Awareness-Quiz\Cyber-Security-Awareness-Quiz\Sonata_Cyber_Quiz\Quiz\views.py", line 86, in employee_kyc_view
    employees = SonataUsersKYCData.objects.filter(Q(EmpID__icontains=search_query) | Q(MobileNo__icontains=search_query) | Q(AdhaarNo__icontains=search_query) | Q(PAN_Number__icontains=search_query) | Q(DOB_icontains = search_query)) # Search query
  File "C:\Users\User\AppData\Roaming\Python\Python313\site-packages\django\db\models\manager.py", line 87, in manager_method
    return getattr(self.get_queryset(), name)(*args, **kwargs)
           ~~~~~~~~~~~~~~~~~~~~~~~~~~~~~~~~~~^^^^^^^^^^^^^^^^^
  File "C:\Users\User\AppData\Roaming\Python\Python313\site-packages\django\db\models\query.py", line 1476, in filter
    return self._filter_or_exclude(False, args, kwargs)
           ~~~~~~~~~~~~~~~~~~~~~~~^^^^^^^^^^^^^^^^^^^^^
  File "C:\Users\User\AppData\Roaming\Python\Python313\site-packages\django\db\models\query.py", line 1494, in _filter_or_exclude
    clone._filter_or_exclude_inplace(negate, args, kwargs)
    ~~~~~~~~~~~~~~~~~~~~~~~~~~~~~~~~^^^^^^^^^^^^^^^^^^^^^^
  File "C:\Users\User\AppData\Roaming\Python\Python313\site-packages\django\db\models\query.py", line 1501, in _filter_or_exclude_inplace
    self._query.add_q(Q(*args, **kwargs))
    ~~~~~~~~~~~~~~~~~^^^^^^^^^^^^^^^^^^^^
  File "C:\Users\User\AppData\Roaming\Python\Python313\site-packages\django\db\models\sql\query.py", line 1613, in add_q
    clause, _ = self._add_q(q_object, self.used_aliases)
                ~~~~~~~~~~~^^^^^^^^^^^^^^^^^^^^^^^^^^^^^
  File "C:\Users\User\AppData\Roaming\Python\Python313\site-packages\django\db\models\sql\query.py", line 1645, in _add_q
    child_clause, needed_inner = self.build_filter(
                                 ~~~~~~~~~~~~~~~~~^
        child,
        ^^^^^^
    ...<7 lines>...
        update_join_types=update_join_types,
        ^^^^^^^^^^^^^^^^^^^^^^^^^^^^^^^^^^^^
    )
    ^
  File "C:\Users\User\AppData\Roaming\Python\Python313\site-packages\django\db\models\sql\query.py", line 1472, in build_filter
    return self._add_q(
           ~~~~~~~~~~~^
        filter_expr,
        ^^^^^^^^^^^^
    ...<7 lines>...
        update_join_types=update_join_types,
        ^^^^^^^^^^^^^^^^^^^^^^^^^^^^^^^^^^^^
    )
    ^
  File "C:\Users\User\AppData\Roaming\Python\Python313\site-packages\django\db\models\sql\query.py", line 1645, in _add_q
    child_clause, needed_inner = self.build_filter(
                                 ~~~~~~~~~~~~~~~~~^
        child,
        ^^^^^^
    ...<7 lines>...
        update_join_types=update_join_types,
        ^^^^^^^^^^^^^^^^^^^^^^^^^^^^^^^^^^^^
    )
    ^
  File "C:\Users\User\AppData\Roaming\Python\Python313\site-packages\django\db\models\sql\query.py", line 1495, in build_filter
    lookups, parts, reffed_expression = self.solve_lookup_type(arg, summarize)
                                        ~~~~~~~~~~~~~~~~~~~~~~^^^^^^^^^^^^^^^^
  File "C:\Users\User\AppData\Roaming\Python\Python313\site-packages\django\db\models\sql\query.py", line 1307, in solve_lookup_type
    _, field, _, lookup_parts = self.names_to_path(lookup_splitted, self.get_meta())
                                ~~~~~~~~~~~~~~~~~~^^^^^^^^^^^^^^^^^^^^^^^^^^^^^^^^^^
  File "C:\Users\User\AppData\Roaming\Python\Python313\site-packages\django\db\models\sql\query.py", line 1772, in names_to_path
    raise FieldError(
    ...<2 lines>...
    )
django.core.exceptions.FieldError: Cannot resolve keyword 'DOB_icontains' into field. Choices are: AdhaarBackImg, AdhaarFrontImg, AdhaarNo, DL_Img, DOB, EmpID, IsActive, IsProcessed, MobileNo, PAN_Img, PAN_Number, Passbook_Img, Photo, RecievedDate, StageID, id
"GET /employee_kyc_view/?search=7527 HTTP/1.1" 500 1427
Internal Server Error: /kyc/
Traceback (most recent call last):
  File "C:\Users\User\AppData\Roaming\Python\Python313\site-packages\django\core\handlers\exception.py", line 55, in inner
    response = get_response(request)
  File "C:\Users\User\AppData\Roaming\Python\Python313\site-packages\django\core\handlers\base.py", line 197, in _get_response
    response = wrapped_callback(request, *callback_args, **callback_kwargs)
  File "C:\Users\User\Downloads\Cyber-Security-Awareness-Quiz\Cyber-Security-Awareness-Quiz\Sonata_Cyber_Quiz\Quiz\views.py", line 86, in employee_kyc_view
    employees = SonataUsersKYCData.objects.filter(Q(EmpID__icontains=search_query) | Q(MobileNo__icontains=search_query) | Q(AdhaarNo__icontains=search_query) | Q(PAN_Number__icontains=search_query) | Q(DOB_icontains = search_query)) # Search query
  File "C:\Users\User\AppData\Roaming\Python\Python313\site-packages\django\db\models\manager.py", line 87, in manager_method
    return getattr(self.get_queryset(), name)(*args, **kwargs)
           ~~~~~~~~~~~~~~~~~~~~~~~~~~~~~~~~~~^^^^^^^^^^^^^^^^^
  File "C:\Users\User\AppData\Roaming\Python\Python313\site-packages\django\db\models\query.py", line 1476, in filter
    return self._filter_or_exclude(False, args, kwargs)
           ~~~~~~~~~~~~~~~~~~~~~~~^^^^^^^^^^^^^^^^^^^^^
  File "C:\Users\User\AppData\Roaming\Python\Python313\site-packages\django\db\models\query.py", line 1494, in _filter_or_exclude
    clone._filter_or_exclude_inplace(negate, args, kwargs)
    ~~~~~~~~~~~~~~~~~~~~~~~~~~~~~~~~^^^^^^^^^^^^^^^^^^^^^^
  File "C:\Users\User\AppData\Roaming\Python\Python313\site-packages\django\db\models\query.py", line 1501, in _filter_or_exclude_inplace
    self._query.add_q(Q(*args, **kwargs))
    ~~~~~~~~~~~~~~~~~^^^^^^^^^^^^^^^^^^^^
  File "C:\Users\User\AppData\Roaming\Python\Python313\site-packages\django\db\models\sql\query.py", line 1613, in add_q
    clause, _ = self._add_q(q_object, self.used_aliases)
                ~~~~~~~~~~~^^^^^^^^^^^^^^^^^^^^^^^^^^^^^
  File "C:\Users\User\AppData\Roaming\Python\Python313\site-packages\django\db\models\sql\query.py", line 1645, in _add_q
    child_clause, needed_inner = self.build_filter(
                                 ~~~~~~~~~~~~~~~~~^
        child,
        ^^^^^^
    ...<7 lines>...
        update_join_types=update_join_types,
        ^^^^^^^^^^^^^^^^^^^^^^^^^^^^^^^^^^^^
    )
    ^
  File "C:\Users\User\AppData\Roaming\Python\Python313\site-packages\django\db\models\sql\query.py", line 1472, in build_filter
    return self._add_q(
           ~~~~~~~~~~~^
        filter_expr,
        ^^^^^^^^^^^^
    ...<7 lines>...
        update_join_types=update_join_types,
        ^^^^^^^^^^^^^^^^^^^^^^^^^^^^^^^^^^^^
    )
    ^
  File "C:\Users\User\AppData\Roaming\Python\Python313\site-packages\django\db\models\sql\query.py", line 1645, in _add_q
    child_clause, needed_inner = self.build_filter(
                                 ~~~~~~~~~~~~~~~~~^
        child,
        ^^^^^^
    ...<7 lines>...
        update_join_types=update_join_types,
        ^^^^^^^^^^^^^^^^^^^^^^^^^^^^^^^^^^^^
    )
    ^
  File "C:\Users\User\AppData\Roaming\Python\Python313\site-packages\django\db\models\sql\query.py", line 1495, in build_filter
    lookups, parts, reffed_expression = self.solve_lookup_type(arg, summarize)
                                        ~~~~~~~~~~~~~~~~~~~~~~^^^^^^^^^^^^^^^^
  File "C:\Users\User\AppData\Roaming\Python\Python313\site-packages\django\db\models\sql\query.py", line 1307, in solve_lookup_type
    _, field, _, lookup_parts = self.names_to_path(lookup_splitted, self.get_meta())
                                ~~~~~~~~~~~~~~~~~~^^^^^^^^^^^^^^^^^^^^^^^^^^^^^^^^^^
  File "C:\Users\User\AppData\Roaming\Python\Python313\site-packages\django\db\models\sql\query.py", line 1772, in names_to_path
    raise FieldError(
    ...<2 lines>...
    )
django.core.exceptions.FieldError: Cannot resolve keyword 'DOB_icontains' into field. Choices are: AdhaarBackImg, AdhaarFrontImg, AdhaarNo, DL_Img, DOB, EmpID, IsActive, IsProcessed, MobileNo, PAN_Img, PAN_Number, Passbook_Img, Photo, RecievedDate, StageID, id
"GET /kyc/?search=7527 HTTP/1.1" 500 1427
Internal Server Error: /kyc/
Traceback (most recent call last):
  File "C:\Users\User\AppData\Roaming\Python\Python313\site-packages\django\core\handlers\exception.py", line 55, in inner
    response = get_response(request)
  File "C:\Users\User\AppData\Roaming\Python\Python313\site-packages\django\core\handlers\base.py", line 197, in _get_response
    response = wrapped_callback(request, *callback_args, **callback_kwargs)
  File "C:\Users\User\Downloads\Cyber-Security-Awareness-Quiz\Cyber-Security-Awareness-Quiz\Sonata_Cyber_Quiz\Quiz\views.py", line 86, in employee_kyc_view
    employees = SonataUsersKYCData.objects.filter(Q(EmpID__icontains=search_query) | Q(MobileNo__icontains=search_query) | Q(AdhaarNo__icontains=search_query) | Q(PAN_Number__icontains=search_query) | Q(DOB_icontains = search_query)) # Search query
  File "C:\Users\User\AppData\Roaming\Python\Python313\site-packages\django\db\models\manager.py", line 87, in manager_method
    return getattr(self.get_queryset(), name)(*args, **kwargs)
           ~~~~~~~~~~~~~~~~~~~~~~~~~~~~~~~~~~^^^^^^^^^^^^^^^^^
  File "C:\Users\User\AppData\Roaming\Python\Python313\site-packages\django\db\models\query.py", line 1476, in filter
    return self._filter_or_exclude(False, args, kwargs)
           ~~~~~~~~~~~~~~~~~~~~~~~^^^^^^^^^^^^^^^^^^^^^
  File "C:\Users\User\AppData\Roaming\Python\Python313\site-packages\django\db\models\query.py", line 1494, in _filter_or_exclude
    clone._filter_or_exclude_inplace(negate, args, kwargs)
    ~~~~~~~~~~~~~~~~~~~~~~~~~~~~~~~~^^^^^^^^^^^^^^^^^^^^^^
  File "C:\Users\User\AppData\Roaming\Python\Python313\site-packages\django\db\models\query.py", line 1501, in _filter_or_exclude_inplace
    self._query.add_q(Q(*args, **kwargs))
    ~~~~~~~~~~~~~~~~~^^^^^^^^^^^^^^^^^^^^
  File "C:\Users\User\AppData\Roaming\Python\Python313\site-packages\django\db\models\sql\query.py", line 1613, in add_q
    clause, _ = self._add_q(q_object, self.used_aliases)
                ~~~~~~~~~~~^^^^^^^^^^^^^^^^^^^^^^^^^^^^^
  File "C:\Users\User\AppData\Roaming\Python\Python313\site-packages\django\db\models\sql\query.py", line 1645, in _add_q
    child_clause, needed_inner = self.build_filter(
                                 ~~~~~~~~~~~~~~~~~^
        child,
        ^^^^^^
    ...<7 lines>...
        update_join_types=update_join_types,
        ^^^^^^^^^^^^^^^^^^^^^^^^^^^^^^^^^^^^
    )
    ^
  File "C:\Users\User\AppData\Roaming\Python\Python313\site-packages\django\db\models\sql\query.py", line 1472, in build_filter
    return self._add_q(
           ~~~~~~~~~~~^
        filter_expr,
        ^^^^^^^^^^^^
    ...<7 lines>...
        update_join_types=update_join_types,
        ^^^^^^^^^^^^^^^^^^^^^^^^^^^^^^^^^^^^
    )
    ^
  File "C:\Users\User\AppData\Roaming\Python\Python313\site-packages\django\db\models\sql\query.py", line 1645, in _add_q
    child_clause, needed_inner = self.build_filter(
                                 ~~~~~~~~~~~~~~~~~^
        child,
        ^^^^^^
    ...<7 lines>...
        update_join_types=update_join_types,
        ^^^^^^^^^^^^^^^^^^^^^^^^^^^^^^^^^^^^
    )
    ^
  File "C:\Users\User\AppData\Roaming\Python\Python313\site-packages\django\db\models\sql\query.py", line 1495, in build_filter
    lookups, parts, reffed_expression = self.solve_lookup_type(arg, summarize)
                                        ~~~~~~~~~~~~~~~~~~~~~~^^^^^^^^^^^^^^^^
  File "C:\Users\User\AppData\Roaming\Python\Python313\site-packages\django\db\models\sql\query.py", line 1307, in solve_lookup_type
    _, field, _, lookup_parts = self.names_to_path(lookup_splitted, self.get_meta())
                                ~~~~~~~~~~~~~~~~~~^^^^^^^^^^^^^^^^^^^^^^^^^^^^^^^^^^
  File "C:\Users\User\AppData\Roaming\Python\Python313\site-packages\django\db\models\sql\query.py", line 1772, in names_to_path
    raise FieldError(
    ...<2 lines>...
    )
django.core.exceptions.FieldError: Cannot resolve keyword 'DOB_icontains' into field. Choices are: AdhaarBackImg, AdhaarFrontImg, AdhaarNo, DL_Img, DOB, EmpID, IsActive, IsProcessed, MobileNo, PAN_Img, PAN_Number, Passbook_Img, Photo, RecievedDate, StageID, id
"GET /kyc/?search=7527 HTTP/1.1" 500 1427
Internal Server Error: /verify-document/
"POST /verify-document/ HTTP/1.1" 500 113
Internal Server Error: /kyc/
Traceback (most recent call last):
  File "C:\Users\User\AppData\Roaming\Python\Python313\site-packages\django\core\handlers\exception.py", line 55, in inner
    response = get_response(request)
  File "C:\Users\User\AppData\Roaming\Python\Python313\site-packages\django\core\handlers\base.py", line 197, in _get_response
    response = wrapped_callback(request, *callback_args, **callback_kwargs)
  File "C:\Users\User\Downloads\Cyber-Security-Awareness-Quiz\Cyber-Security-Awareness-Quiz\Sonata_Cyber_Quiz\Quiz\views.py", line 86, in employee_kyc_view
    employees = SonataUsersKYCData.objects.filter(Q(EmpID__icontains=search_query) | Q(MobileNo__icontains=search_query) | Q(AdhaarNo__icontains=search_query) | Q(PAN_Number__icontains=search_query) | Q(DOB_icontains = search_query)) # Search query
  File "C:\Users\User\AppData\Roaming\Python\Python313\site-packages\django\db\models\manager.py", line 87, in manager_method
    return getattr(self.get_queryset(), name)(*args, **kwargs)
           ~~~~~~~~~~~~~~~~~~~~~~~~~~~~~~~~~~^^^^^^^^^^^^^^^^^
  File "C:\Users\User\AppData\Roaming\Python\Python313\site-packages\django\db\models\query.py", line 1476, in filter
    return self._filter_or_exclude(False, args, kwargs)
           ~~~~~~~~~~~~~~~~~~~~~~~^^^^^^^^^^^^^^^^^^^^^
  File "C:\Users\User\AppData\Roaming\Python\Python313\site-packages\django\db\models\query.py", line 1494, in _filter_or_exclude
    clone._filter_or_exclude_inplace(negate, args, kwargs)
    ~~~~~~~~~~~~~~~~~~~~~~~~~~~~~~~~^^^^^^^^^^^^^^^^^^^^^^
  File "C:\Users\User\AppData\Roaming\Python\Python313\site-packages\django\db\models\query.py", line 1501, in _filter_or_exclude_inplace
    self._query.add_q(Q(*args, **kwargs))
    ~~~~~~~~~~~~~~~~~^^^^^^^^^^^^^^^^^^^^
  File "C:\Users\User\AppData\Roaming\Python\Python313\site-packages\django\db\models\sql\query.py", line 1613, in add_q
    clause, _ = self._add_q(q_object, self.used_aliases)
                ~~~~~~~~~~~^^^^^^^^^^^^^^^^^^^^^^^^^^^^^
  File "C:\Users\User\AppData\Roaming\Python\Python313\site-packages\django\db\models\sql\query.py", line 1645, in _add_q
    child_clause, needed_inner = self.build_filter(
                                 ~~~~~~~~~~~~~~~~~^
        child,
        ^^^^^^
    ...<7 lines>...
        update_join_types=update_join_types,
        ^^^^^^^^^^^^^^^^^^^^^^^^^^^^^^^^^^^^
    )
    ^
  File "C:\Users\User\AppData\Roaming\Python\Python313\site-packages\django\db\models\sql\query.py", line 1472, in build_filter
    return self._add_q(
           ~~~~~~~~~~~^
        filter_expr,
        ^^^^^^^^^^^^
    ...<7 lines>...
        update_join_types=update_join_types,
        ^^^^^^^^^^^^^^^^^^^^^^^^^^^^^^^^^^^^
    )
    ^
  File "C:\Users\User\AppData\Roaming\Python\Python313\site-packages\django\db\models\sql\query.py", line 1645, in _add_q
    child_clause, needed_inner = self.build_filter(
                                 ~~~~~~~~~~~~~~~~~^
        child,
        ^^^^^^
    ...<7 lines>...
        update_join_types=update_join_types,
        ^^^^^^^^^^^^^^^^^^^^^^^^^^^^^^^^^^^^
    )
    ^
  File "C:\Users\User\AppData\Roaming\Python\Python313\site-packages\django\db\models\sql\query.py", line 1495, in build_filter
    lookups, parts, reffed_expression = self.solve_lookup_type(arg, summarize)
                                        ~~~~~~~~~~~~~~~~~~~~~~^^^^^^^^^^^^^^^^
  File "C:\Users\User\AppData\Roaming\Python\Python313\site-packages\django\db\models\sql\query.py", line 1307, in solve_lookup_type
    _, field, _, lookup_parts = self.names_to_path(lookup_splitted, self.get_meta())
                                ~~~~~~~~~~~~~~~~~~^^^^^^^^^^^^^^^^^^^^^^^^^^^^^^^^^^
  File "C:\Users\User\AppData\Roaming\Python\Python313\site-packages\django\db\models\sql\query.py", line 1772, in names_to_path
    raise FieldError(
    ...<2 lines>...
    )
django.core.exceptions.FieldError: Cannot resolve keyword 'DOB_icontains' into field. Choices are: AdhaarBackImg, AdhaarFrontImg, AdhaarNo, DL_Img, DOB, EmpID, FinalVerified_by, IsActive, IsProcessed, MobileNo, PAN_Img, PAN_Number, Passbook_Img, Photo, RecievedDate, StageID, id
"GET /kyc/?search=7748 HTTP/1.1" 500 1427
Internal Server Error: /kyc/
Traceback (most recent call last):
  File "C:\Users\User\AppData\Roaming\Python\Python313\site-packages\django\core\handlers\exception.py", line 55, in inner
    response = get_response(request)
  File "C:\Users\User\AppData\Roaming\Python\Python313\site-packages\django\core\handlers\base.py", line 197, in _get_response
    response = wrapped_callback(request, *callback_args, **callback_kwargs)
  File "C:\Users\User\Downloads\Cyber-Security-Awareness-Quiz\Cyber-Security-Awareness-Quiz\Sonata_Cyber_Quiz\Quiz\views.py", line 86, in employee_kyc_view
    employees = SonataUsersKYCData.objects.filter(Q(EmpID__icontains=search_query) | Q(MobileNo__icontains=search_query) | Q(AdhaarNo__icontains=search_query) | Q(PAN_Number__icontains=search_query) | Q(DOB_icontains = search_query)) # Search query
  File "C:\Users\User\AppData\Roaming\Python\Python313\site-packages\django\db\models\manager.py", line 87, in manager_method
    return getattr(self.get_queryset(), name)(*args, **kwargs)
           ~~~~~~~~~~~~~~~~~~~~~~~~~~~~~~~~~~^^^^^^^^^^^^^^^^^
  File "C:\Users\User\AppData\Roaming\Python\Python313\site-packages\django\db\models\query.py", line 1476, in filter
    return self._filter_or_exclude(False, args, kwargs)
           ~~~~~~~~~~~~~~~~~~~~~~~^^^^^^^^^^^^^^^^^^^^^
  File "C:\Users\User\AppData\Roaming\Python\Python313\site-packages\django\db\models\query.py", line 1494, in _filter_or_exclude
    clone._filter_or_exclude_inplace(negate, args, kwargs)
    ~~~~~~~~~~~~~~~~~~~~~~~~~~~~~~~~^^^^^^^^^^^^^^^^^^^^^^
  File "C:\Users\User\AppData\Roaming\Python\Python313\site-packages\django\db\models\query.py", line 1501, in _filter_or_exclude_inplace
    self._query.add_q(Q(*args, **kwargs))
    ~~~~~~~~~~~~~~~~~^^^^^^^^^^^^^^^^^^^^
  File "C:\Users\User\AppData\Roaming\Python\Python313\site-packages\django\db\models\sql\query.py", line 1613, in add_q
    clause, _ = self._add_q(q_object, self.used_aliases)
                ~~~~~~~~~~~^^^^^^^^^^^^^^^^^^^^^^^^^^^^^
  File "C:\Users\User\AppData\Roaming\Python\Python313\site-packages\django\db\models\sql\query.py", line 1645, in _add_q
    child_clause, needed_inner = self.build_filter(
                                 ~~~~~~~~~~~~~~~~~^
        child,
        ^^^^^^
    ...<7 lines>...
        update_join_types=update_join_types,
        ^^^^^^^^^^^^^^^^^^^^^^^^^^^^^^^^^^^^
    )
    ^
  File "C:\Users\User\AppData\Roaming\Python\Python313\site-packages\django\db\models\sql\query.py", line 1472, in build_filter
    return self._add_q(
           ~~~~~~~~~~~^
        filter_expr,
        ^^^^^^^^^^^^
    ...<7 lines>...
        update_join_types=update_join_types,
        ^^^^^^^^^^^^^^^^^^^^^^^^^^^^^^^^^^^^
    )
    ^
  File "C:\Users\User\AppData\Roaming\Python\Python313\site-packages\django\db\models\sql\query.py", line 1645, in _add_q
    child_clause, needed_inner = self.build_filter(
                                 ~~~~~~~~~~~~~~~~~^
        child,
        ^^^^^^
    ...<7 lines>...
        update_join_types=update_join_types,
        ^^^^^^^^^^^^^^^^^^^^^^^^^^^^^^^^^^^^
    )
    ^
  File "C:\Users\User\AppData\Roaming\Python\Python313\site-packages\django\db\models\sql\query.py", line 1495, in build_filter
    lookups, parts, reffed_expression = self.solve_lookup_type(arg, summarize)
                                        ~~~~~~~~~~~~~~~~~~~~~~^^^^^^^^^^^^^^^^
  File "C:\Users\User\AppData\Roaming\Python\Python313\site-packages\django\db\models\sql\query.py", line 1307, in solve_lookup_type
    _, field, _, lookup_parts = self.names_to_path(lookup_splitted, self.get_meta())
                                ~~~~~~~~~~~~~~~~~~^^^^^^^^^^^^^^^^^^^^^^^^^^^^^^^^^^
  File "C:\Users\User\AppData\Roaming\Python\Python313\site-packages\django\db\models\sql\query.py", line 1772, in names_to_path
    raise FieldError(
    ...<2 lines>...
    )
django.core.exceptions.FieldError: Cannot resolve keyword 'DOB_icontains' into field. Choices are: AdhaarBackImg, AdhaarFrontImg, AdhaarNo, DL_Img, DOB, EmpID, FinalVerified_by, IsActive, IsProcessed, MobileNo, PAN_Img, PAN_Number, Passbook_Img, Photo, RecievedDate, StageID, id
"GET /kyc/?search=7748 HTTP/1.1" 500 1427
Internal Server Error: /HR_dashboard/
Traceback (most recent call last):
  File "C:\Users\User\AppData\Roaming\Python\Python313\site-packages\pandas\core\internals\construction.py", line 939, in _finalize_columns_and_data
    columns = _validate_or_indexify_columns(contents, columns)
  File "C:\Users\User\AppData\Roaming\Python\Python313\site-packages\pandas\core\internals\construction.py", line 986, in _validate_or_indexify_columns
    raise AssertionError(
    ...<2 lines>...
    )
AssertionError: 8 columns passed, passed data had 6 columns

The above exception was the direct cause of the following exception:

Traceback (most recent call last):
  File "C:\Users\User\AppData\Roaming\Python\Python313\site-packages\django\core\handlers\exception.py", line 55, in inner
    response = get_response(request)
  File "C:\Users\User\AppData\Roaming\Python\Python313\site-packages\django\core\handlers\base.py", line 197, in _get_response
    response = wrapped_callback(request, *callback_args, **callback_kwargs)
  File "E:\Laptop Data\Cyber-Security-Awareness-Quiz\Cyber-Security-Awareness-Quiz\Sonata_Cyber_Quiz\Quiz\views.py", line 150, in HR_dashboard
    df = pd.DataFrame(employee_data, columns=columns)  # Convert to DataFrame
  File "C:\Users\User\AppData\Roaming\Python\Python313\site-packages\pandas\core\frame.py", line 851, in __init__
    arrays, columns, index = nested_data_to_arrays(
                             ~~~~~~~~~~~~~~~~~~~~~^
        # error: Argument 3 to "nested_data_to_arrays" has incompatible
        ^^^^^^^^^^^^^^^^^^^^^^^^^^^^^^^^^^^^^^^^^^^^^^^^^^^^^^^^^^^^^^^
    ...<4 lines>...
        dtype,
        ^^^^^^
    )
    ^
  File "C:\Users\User\AppData\Roaming\Python\Python313\site-packages\pandas\core\internals\construction.py", line 520, in nested_data_to_arrays
    arrays, columns = to_arrays(data, columns, dtype=dtype)
                      ~~~~~~~~~^^^^^^^^^^^^^^^^^^^^^^^^^^^^
  File "C:\Users\User\AppData\Roaming\Python\Python313\site-packages\pandas\core\internals\construction.py", line 845, in to_arrays
    content, columns = _finalize_columns_and_data(arr, columns, dtype)
                       ~~~~~~~~~~~~~~~~~~~~~~~~~~^^^^^^^^^^^^^^^^^^^^^
  File "C:\Users\User\AppData\Roaming\Python\Python313\site-packages\pandas\core\internals\construction.py", line 942, in _finalize_columns_and_data
    raise ValueError(err) from err
ValueError: 8 columns passed, passed data had 6 columns
"GET /HR_dashboard/ HTTP/1.1" 500 1427
Internal Server Error: /HR_dashboard/
Traceback (most recent call last):
  File "C:\Users\User\AppData\Roaming\Python\Python313\site-packages\pandas\core\internals\construction.py", line 939, in _finalize_columns_and_data
    columns = _validate_or_indexify_columns(contents, columns)
  File "C:\Users\User\AppData\Roaming\Python\Python313\site-packages\pandas\core\internals\construction.py", line 986, in _validate_or_indexify_columns
    raise AssertionError(
    ...<2 lines>...
    )
AssertionError: 8 columns passed, passed data had 6 columns

The above exception was the direct cause of the following exception:

Traceback (most recent call last):
  File "C:\Users\User\AppData\Roaming\Python\Python313\site-packages\django\core\handlers\exception.py", line 55, in inner
    response = get_response(request)
  File "C:\Users\User\AppData\Roaming\Python\Python313\site-packages\django\core\handlers\base.py", line 197, in _get_response
    response = wrapped_callback(request, *callback_args, **callback_kwargs)
  File "E:\Laptop Data\Cyber-Security-Awareness-Quiz\Cyber-Security-Awareness-Quiz\Sonata_Cyber_Quiz\Quiz\views.py", line 150, in HR_dashboard
    df = pd.DataFrame(employee_data, columns=columns)  # Convert to DataFrame
  File "C:\Users\User\AppData\Roaming\Python\Python313\site-packages\pandas\core\frame.py", line 851, in __init__
    arrays, columns, index = nested_data_to_arrays(
                             ~~~~~~~~~~~~~~~~~~~~~^
        # error: Argument 3 to "nested_data_to_arrays" has incompatible
        ^^^^^^^^^^^^^^^^^^^^^^^^^^^^^^^^^^^^^^^^^^^^^^^^^^^^^^^^^^^^^^^
    ...<4 lines>...
        dtype,
        ^^^^^^
    )
    ^
  File "C:\Users\User\AppData\Roaming\Python\Python313\site-packages\pandas\core\internals\construction.py", line 520, in nested_data_to_arrays
    arrays, columns = to_arrays(data, columns, dtype=dtype)
                      ~~~~~~~~~^^^^^^^^^^^^^^^^^^^^^^^^^^^^
  File "C:\Users\User\AppData\Roaming\Python\Python313\site-packages\pandas\core\internals\construction.py", line 845, in to_arrays
    content, columns = _finalize_columns_and_data(arr, columns, dtype)
                       ~~~~~~~~~~~~~~~~~~~~~~~~~~^^^^^^^^^^^^^^^^^^^^^
  File "C:\Users\User\AppData\Roaming\Python\Python313\site-packages\pandas\core\internals\construction.py", line 942, in _finalize_columns_and_data
    raise ValueError(err) from err
ValueError: 8 columns passed, passed data had 6 columns
"GET /HR_dashboard/ HTTP/1.1" 500 1427
Internal Server Error: /HR_dashboard/
Traceback (most recent call last):
  File "C:\Users\User\AppData\Roaming\Python\Python313\site-packages\pandas\core\internals\construction.py", line 939, in _finalize_columns_and_data
    columns = _validate_or_indexify_columns(contents, columns)
  File "C:\Users\User\AppData\Roaming\Python\Python313\site-packages\pandas\core\internals\construction.py", line 986, in _validate_or_indexify_columns
    raise AssertionError(
    ...<2 lines>...
    )
AssertionError: 8 columns passed, passed data had 6 columns

The above exception was the direct cause of the following exception:

Traceback (most recent call last):
  File "C:\Users\User\AppData\Roaming\Python\Python313\site-packages\django\core\handlers\exception.py", line 55, in inner
    response = get_response(request)
  File "C:\Users\User\AppData\Roaming\Python\Python313\site-packages\django\core\handlers\base.py", line 197, in _get_response
    response = wrapped_callback(request, *callback_args, **callback_kwargs)
  File "E:\Laptop Data\Cyber-Security-Awareness-Quiz\Cyber-Security-Awareness-Quiz\Sonata_Cyber_Quiz\Quiz\views.py", line 150, in HR_dashboard
    df = pd.DataFrame(employee_data, columns=columns)  # Convert to DataFrame
  File "C:\Users\User\AppData\Roaming\Python\Python313\site-packages\pandas\core\frame.py", line 851, in __init__
    arrays, columns, index = nested_data_to_arrays(
                             ~~~~~~~~~~~~~~~~~~~~~^
        # error: Argument 3 to "nested_data_to_arrays" has incompatible
        ^^^^^^^^^^^^^^^^^^^^^^^^^^^^^^^^^^^^^^^^^^^^^^^^^^^^^^^^^^^^^^^
    ...<4 lines>...
        dtype,
        ^^^^^^
    )
    ^
  File "C:\Users\User\AppData\Roaming\Python\Python313\site-packages\pandas\core\internals\construction.py", line 520, in nested_data_to_arrays
    arrays, columns = to_arrays(data, columns, dtype=dtype)
                      ~~~~~~~~~^^^^^^^^^^^^^^^^^^^^^^^^^^^^
  File "C:\Users\User\AppData\Roaming\Python\Python313\site-packages\pandas\core\internals\construction.py", line 845, in to_arrays
    content, columns = _finalize_columns_and_data(arr, columns, dtype)
                       ~~~~~~~~~~~~~~~~~~~~~~~~~~^^^^^^^^^^^^^^^^^^^^^
  File "C:\Users\User\AppData\Roaming\Python\Python313\site-packages\pandas\core\internals\construction.py", line 942, in _finalize_columns_and_data
    raise ValueError(err) from err
ValueError: 8 columns passed, passed data had 6 columns
"GET /HR_dashboard/ HTTP/1.1" 500 1427
Internal Server Error: /HR_dashboard/
Traceback (most recent call last):
  File "C:\Users\User\AppData\Roaming\Python\Python313\site-packages\pandas\core\internals\construction.py", line 939, in _finalize_columns_and_data
    columns = _validate_or_indexify_columns(contents, columns)
  File "C:\Users\User\AppData\Roaming\Python\Python313\site-packages\pandas\core\internals\construction.py", line 986, in _validate_or_indexify_columns
    raise AssertionError(
    ...<2 lines>...
    )
AssertionError: 8 columns passed, passed data had 6 columns

The above exception was the direct cause of the following exception:

Traceback (most recent call last):
  File "C:\Users\User\AppData\Roaming\Python\Python313\site-packages\django\core\handlers\exception.py", line 55, in inner
    response = get_response(request)
  File "C:\Users\User\AppData\Roaming\Python\Python313\site-packages\django\core\handlers\base.py", line 197, in _get_response
    response = wrapped_callback(request, *callback_args, **callback_kwargs)
  File "E:\Laptop Data\Cyber-Security-Awareness-Quiz\Cyber-Security-Awareness-Quiz\Sonata_Cyber_Quiz\Quiz\views.py", line 150, in HR_dashboard
    df = pd.DataFrame(employee_data, columns=columns)  # Convert to DataFrame
  File "C:\Users\User\AppData\Roaming\Python\Python313\site-packages\pandas\core\frame.py", line 851, in __init__
    arrays, columns, index = nested_data_to_arrays(
                             ~~~~~~~~~~~~~~~~~~~~~^
        # error: Argument 3 to "nested_data_to_arrays" has incompatible
        ^^^^^^^^^^^^^^^^^^^^^^^^^^^^^^^^^^^^^^^^^^^^^^^^^^^^^^^^^^^^^^^
    ...<4 lines>...
        dtype,
        ^^^^^^
    )
    ^
  File "C:\Users\User\AppData\Roaming\Python\Python313\site-packages\pandas\core\internals\construction.py", line 520, in nested_data_to_arrays
    arrays, columns = to_arrays(data, columns, dtype=dtype)
                      ~~~~~~~~~^^^^^^^^^^^^^^^^^^^^^^^^^^^^
  File "C:\Users\User\AppData\Roaming\Python\Python313\site-packages\pandas\core\internals\construction.py", line 845, in to_arrays
    content, columns = _finalize_columns_and_data(arr, columns, dtype)
                       ~~~~~~~~~~~~~~~~~~~~~~~~~~^^^^^^^^^^^^^^^^^^^^^
  File "C:\Users\User\AppData\Roaming\Python\Python313\site-packages\pandas\core\internals\construction.py", line 942, in _finalize_columns_and_data
    raise ValueError(err) from err
ValueError: 8 columns passed, passed data had 6 columns
"GET /HR_dashboard/ HTTP/1.1" 500 1427
Internal Server Error: /HR_dashboard/
Traceback (most recent call last):
  File "C:\Users\User\AppData\Roaming\Python\Python313\site-packages\pandas\core\internals\construction.py", line 939, in _finalize_columns_and_data
    columns = _validate_or_indexify_columns(contents, columns)
  File "C:\Users\User\AppData\Roaming\Python\Python313\site-packages\pandas\core\internals\construction.py", line 986, in _validate_or_indexify_columns
    raise AssertionError(
    ...<2 lines>...
    )
AssertionError: 8 columns passed, passed data had 6 columns

The above exception was the direct cause of the following exception:

Traceback (most recent call last):
  File "C:\Users\User\AppData\Roaming\Python\Python313\site-packages\django\core\handlers\exception.py", line 55, in inner
    response = get_response(request)
  File "C:\Users\User\AppData\Roaming\Python\Python313\site-packages\django\core\handlers\base.py", line 197, in _get_response
    response = wrapped_callback(request, *callback_args, **callback_kwargs)
  File "E:\Laptop Data\Cyber-Security-Awareness-Quiz\Cyber-Security-Awareness-Quiz\Sonata_Cyber_Quiz\Quiz\views.py", line 150, in HR_dashboard
    df = pd.DataFrame(employee_data, columns=columns)  # Convert to DataFrame
  File "C:\Users\User\AppData\Roaming\Python\Python313\site-packages\pandas\core\frame.py", line 851, in __init__
    arrays, columns, index = nested_data_to_arrays(
                             ~~~~~~~~~~~~~~~~~~~~~^
        # error: Argument 3 to "nested_data_to_arrays" has incompatible
        ^^^^^^^^^^^^^^^^^^^^^^^^^^^^^^^^^^^^^^^^^^^^^^^^^^^^^^^^^^^^^^^
    ...<4 lines>...
        dtype,
        ^^^^^^
    )
    ^
  File "C:\Users\User\AppData\Roaming\Python\Python313\site-packages\pandas\core\internals\construction.py", line 520, in nested_data_to_arrays
    arrays, columns = to_arrays(data, columns, dtype=dtype)
                      ~~~~~~~~~^^^^^^^^^^^^^^^^^^^^^^^^^^^^
  File "C:\Users\User\AppData\Roaming\Python\Python313\site-packages\pandas\core\internals\construction.py", line 845, in to_arrays
    content, columns = _finalize_columns_and_data(arr, columns, dtype)
                       ~~~~~~~~~~~~~~~~~~~~~~~~~~^^^^^^^^^^^^^^^^^^^^^
  File "C:\Users\User\AppData\Roaming\Python\Python313\site-packages\pandas\core\internals\construction.py", line 942, in _finalize_columns_and_data
    raise ValueError(err) from err
ValueError: 8 columns passed, passed data had 6 columns
"GET /HR_dashboard/ HTTP/1.1" 500 159362
Internal Server Error: /get-emp-images/
Traceback (most recent call last):
  File "C:\Users\User\AppData\Roaming\Python\Python313\site-packages\django\core\handlers\exception.py", line 55, in inner
    response = get_response(request)
  File "C:\Users\User\AppData\Roaming\Python\Python313\site-packages\django\core\handlers\base.py", line 197, in _get_response
    response = wrapped_callback(request, *callback_args, **callback_kwargs)
  File "E:\Laptop Data\Cyber-Security-Awareness-Quiz\Cyber-Security-Awareness-Quiz\Sonata_Cyber_Quiz\Quiz\views.py", line 240, in get_emp_images
    'ProfileImage': convert_binary_to_base64(row[34]),
                    ~~~~~~~~~~~~~~~~~~~~~~~~^^^^^^^^^
  File "E:\Laptop Data\Cyber-Security-Awareness-Quiz\Cyber-Security-Awareness-Quiz\Sonata_Cyber_Quiz\Quiz\views.py", line 252, in convert_binary_to_base64
    return "data:image/png;base64," + base64.b64encode(binary_data).decode('utf-8')
                                      ~~~~~~~~~~~~~~~~^^^^^^^^^^^^^
  File "C:\Python313\Lib\base64.py", line 58, in b64encode
    encoded = binascii.b2a_base64(s, newline=False)
TypeError: a bytes-like object is required, not 'str'
"GET /get-emp-images/?empid=7734 HTTP/1.1" 500 81593
Internal Server Error: /HR_dashboard/
Traceback (most recent call last):
  File "C:\Users\User\AppData\Roaming\Python\Python313\site-packages\pandas\core\internals\construction.py", line 939, in _finalize_columns_and_data
    columns = _validate_or_indexify_columns(contents, columns)
  File "C:\Users\User\AppData\Roaming\Python\Python313\site-packages\pandas\core\internals\construction.py", line 986, in _validate_or_indexify_columns
    raise AssertionError(
    ...<2 lines>...
    )
AssertionError: 9 columns passed, passed data had 8 columns

The above exception was the direct cause of the following exception:

Traceback (most recent call last):
  File "C:\Users\User\AppData\Roaming\Python\Python313\site-packages\django\core\handlers\exception.py", line 55, in inner
    response = get_response(request)
  File "C:\Users\User\AppData\Roaming\Python\Python313\site-packages\django\core\handlers\base.py", line 197, in _get_response
    response = wrapped_callback(request, *callback_args, **callback_kwargs)
  File "E:\Laptop Data\Cyber-Security-Awareness-Quiz\Cyber-Security-Awareness-Quiz\Sonata_Cyber_Quiz\Quiz\views.py", line 164, in HR_dashboard
    df = pd.DataFrame(employee_data, columns=columns)  # Convert to DataFrame
  File "C:\Users\User\AppData\Roaming\Python\Python313\site-packages\pandas\core\frame.py", line 851, in __init__
    arrays, columns, index = nested_data_to_arrays(
                             ~~~~~~~~~~~~~~~~~~~~~^
        # error: Argument 3 to "nested_data_to_arrays" has incompatible
        ^^^^^^^^^^^^^^^^^^^^^^^^^^^^^^^^^^^^^^^^^^^^^^^^^^^^^^^^^^^^^^^
    ...<4 lines>...
        dtype,
        ^^^^^^
    )
    ^
  File "C:\Users\User\AppData\Roaming\Python\Python313\site-packages\pandas\core\internals\construction.py", line 520, in nested_data_to_arrays
    arrays, columns = to_arrays(data, columns, dtype=dtype)
                      ~~~~~~~~~^^^^^^^^^^^^^^^^^^^^^^^^^^^^
  File "C:\Users\User\AppData\Roaming\Python\Python313\site-packages\pandas\core\internals\construction.py", line 845, in to_arrays
    content, columns = _finalize_columns_and_data(arr, columns, dtype)
                       ~~~~~~~~~~~~~~~~~~~~~~~~~~^^^^^^^^^^^^^^^^^^^^^
  File "C:\Users\User\AppData\Roaming\Python\Python313\site-packages\pandas\core\internals\construction.py", line 942, in _finalize_columns_and_data
    raise ValueError(err) from err
ValueError: 9 columns passed, passed data had 8 columns
"GET /HR_dashboard/ HTTP/1.1" 500 165714
Internal Server Error: /download-excel-reports/
"GET /download-excel-reports/?type=completed&start=2025-03-29&end=2025-03-29 HTTP/1.1" 500 130
Internal Server Error: /download-excel-reports/
"GET /download-excel-reports/?type=completed&start=2025-03-29&end=2025-03-29 HTTP/1.1" 500 130
Internal Server Error: /download-excel-reports/
"GET /download-excel-reports/?type=completed&start=2025-03-29&end=2025-03-29 HTTP/1.1" 500 130
Internal Server Error: /download-excel-reports/
"GET /download-excel-reports/?type=completed&start=2025-03-29&end=2025-03-29 HTTP/1.1" 500 130
Internal Server Error: /
Traceback (most recent call last):
  File "C:\Users\User\AppData\Roaming\Python\Python313\site-packages\django\db\backends\base\base.py", line 275, in ensure_connection
    self.connect()
    ~~~~~~~~~~~~^^
  File "C:\Users\User\AppData\Roaming\Python\Python313\site-packages\django\utils\asyncio.py", line 26, in inner
    return func(*args, **kwargs)
  File "C:\Users\User\AppData\Roaming\Python\Python313\site-packages\django\db\backends\base\base.py", line 256, in connect
    self.connection = self.get_new_connection(conn_params)
                      ~~~~~~~~~~~~~~~~~~~~~~~^^^^^^^^^^^^^
  File "C:\Users\User\AppData\Roaming\Python\Python313\site-packages\mssql\base.py", line 368, in get_new_connection
    conn = Database.connect(connstr, **args)
pyodbc.InterfaceError: ('28000', "[28000] [Microsoft][ODBC Driver 17 for SQL Server][SQL Server]Login failed for user 'SFPL_HR'. (18456) (SQLDriverConnect); [28000] [Microsoft][ODBC Driver 17 for SQL Server]Invalid connection string attribute (0); [28000] [Microsoft][ODBC Driver 17 for SQL Server][SQL Server]Login failed for user 'SFPL_HR'. (18456); [28000] [Microsoft][ODBC Driver 17 for SQL Server]Invalid connection string attribute (0)")

The above exception was the direct cause of the following exception:

Traceback (most recent call last):
  File "C:\Users\User\AppData\Roaming\Python\Python313\site-packages\django\core\handlers\exception.py", line 55, in inner
    response = get_response(request)
  File "C:\Users\User\AppData\Roaming\Python\Python313\site-packages\django\core\handlers\base.py", line 197, in _get_response
    response = wrapped_callback(request, *callback_args, **callback_kwargs)
  File "E:\Laptop Data\Cyber-Security-Awareness-Quiz\Cyber-Security-Awareness-Quiz\Sonata_Cyber_Quiz\Quiz\views.py", line 41, in home
    with connections['second_db'].cursor() as cursor:
         ~~~~~~~~~~~~~~~~~~~~~~~~~~~~~~~^^
  File "C:\Users\User\AppData\Roaming\Python\Python313\site-packages\django\utils\asyncio.py", line 26, in inner
    return func(*args, **kwargs)
  File "C:\Users\User\AppData\Roaming\Python\Python313\site-packages\django\db\backends\base\base.py", line 316, in cursor
    return self._cursor()
           ~~~~~~~~~~~~^^
  File "C:\Users\User\AppData\Roaming\Python\Python313\site-packages\mssql\base.py", line 261, in _cursor
    conn = super()._cursor()
  File "C:\Users\User\AppData\Roaming\Python\Python313\site-packages\django\db\backends\base\base.py", line 292, in _cursor
    self.ensure_connection()
    ~~~~~~~~~~~~~~~~~~~~~~^^
  File "C:\Users\User\AppData\Roaming\Python\Python313\site-packages\django\utils\asyncio.py", line 26, in inner
    return func(*args, **kwargs)
  File "C:\Users\User\AppData\Roaming\Python\Python313\site-packages\django\db\backends\base\base.py", line 274, in ensure_connection
    with self.wrap_database_errors:
         ^^^^^^^^^^^^^^^^^^^^^^^^^
  File "C:\Users\User\AppData\Roaming\Python\Python313\site-packages\django\db\utils.py", line 91, in __exit__
    raise dj_exc_value.with_traceback(traceback) from exc_value
  File "C:\Users\User\AppData\Roaming\Python\Python313\site-packages\django\db\backends\base\base.py", line 275, in ensure_connection
    self.connect()
    ~~~~~~~~~~~~^^
  File "C:\Users\User\AppData\Roaming\Python\Python313\site-packages\django\utils\asyncio.py", line 26, in inner
    return func(*args, **kwargs)
  File "C:\Users\User\AppData\Roaming\Python\Python313\site-packages\django\db\backends\base\base.py", line 256, in connect
    self.connection = self.get_new_connection(conn_params)
                      ~~~~~~~~~~~~~~~~~~~~~~~^^^^^^^^^^^^^
  File "C:\Users\User\AppData\Roaming\Python\Python313\site-packages\mssql\base.py", line 368, in get_new_connection
    conn = Database.connect(connstr, **args)
django.db.utils.InterfaceError: ('28000', "[28000] [Microsoft][ODBC Driver 17 for SQL Server][SQL Server]Login failed for user 'SFPL_HR'. (18456) (SQLDriverConnect); [28000] [Microsoft][ODBC Driver 17 for SQL Server]Invalid connection string attribute (0); [28000] [Microsoft][ODBC Driver 17 for SQL Server][SQL Server]Login failed for user 'SFPL_HR'. (18456); [28000] [Microsoft][ODBC Driver 17 for SQL Server]Invalid connection string attribute (0)")
"POST / HTTP/1.1" 500 147311
Internal Server Error: /verify-document/
"POST /verify-document/ HTTP/1.1" 500 119
Internal Server Error: /verify-document/
"POST /verify-document/ HTTP/1.1" 500 119
Internal Server Error: /verify-document/
"POST /verify-document/ HTTP/1.1" 500 119
Internal Server Error: /download-excel-reports/
"GET /download-excel-reports/?type=pending&start=2025-03-21&end=2025-04-01 HTTP/1.1" 500 153
Internal Server Error: /download-excel-reports/
"GET /download-excel-reports/?type=completed&start=2025-03-30&end=2025-04-01 HTTP/1.1" 500 132
Internal Server Error: /download-excel-reports/
"GET /download-excel-reports/?type=completed&start=2025-03-30&end=2025-04-01 HTTP/1.1" 500 58
Internal Server Error: /download-excel-reports/
"GET /download-excel-reports/?type=completed&start=2025-03-30&end=2025-04-01 HTTP/1.1" 500 45
Internal Server Error: /download-excel-reports/
"GET /download-excel-reports/?type=completed&start=2025-03-30&end=2025-04-01 HTTP/1.1" 500 38
Internal Server Error: /download-excel-reports/
"GET /download-excel-reports/?type=pending&start=2025-03-30&end=2025-04-01 HTTP/1.1" 500 131
Internal Server Error: /download-excel-reports/
"GET /download-excel-reports/?type=pending&start=2025-04-01&end=2025-04-01 HTTP/1.1" 500 131
Internal Server Error: /download-excel-reports/
"GET /download-excel-reports/?type=reject&start=2025-03-30&end=2025-04-01 HTTP/1.1" 500 80
Internal Server Error: /HR_dashboard/
Traceback (most recent call last):
  File "C:\Users\User\AppData\Roaming\Python\Python313\site-packages\pandas\core\internals\construction.py", line 939, in _finalize_columns_and_data
    columns = _validate_or_indexify_columns(contents, columns)
  File "C:\Users\User\AppData\Roaming\Python\Python313\site-packages\pandas\core\internals\construction.py", line 986, in _validate_or_indexify_columns
    raise AssertionError(
    ...<2 lines>...
    )
AssertionError: 9 columns passed, passed data had 1 columns

The above exception was the direct cause of the following exception:

Traceback (most recent call last):
  File "C:\Users\User\AppData\Roaming\Python\Python313\site-packages\django\core\handlers\exception.py", line 55, in inner
    response = get_response(request)
  File "C:\Users\User\AppData\Roaming\Python\Python313\site-packages\django\core\handlers\base.py", line 197, in _get_response
    response = wrapped_callback(request, *callback_args, **callback_kwargs)
  File "E:\Laptop Data\Cyber-Security-Awareness-Quiz\Cyber-Security-Awareness-Quiz\Sonata_Cyber_Quiz\Quiz\views.py", line 191, in HR_dashboard
    pending_df = pd.DataFrame(pending_employee_data, columns=columns)  # Convert to DataFrame
  File "C:\Users\User\AppData\Roaming\Python\Python313\site-packages\pandas\core\frame.py", line 851, in __init__
    arrays, columns, index = nested_data_to_arrays(
                             ~~~~~~~~~~~~~~~~~~~~~^
        # error: Argument 3 to "nested_data_to_arrays" has incompatible
        ^^^^^^^^^^^^^^^^^^^^^^^^^^^^^^^^^^^^^^^^^^^^^^^^^^^^^^^^^^^^^^^
    ...<4 lines>...
        dtype,
        ^^^^^^
    )
    ^
  File "C:\Users\User\AppData\Roaming\Python\Python313\site-packages\pandas\core\internals\construction.py", line 520, in nested_data_to_arrays
    arrays, columns = to_arrays(data, columns, dtype=dtype)
                      ~~~~~~~~~^^^^^^^^^^^^^^^^^^^^^^^^^^^^
  File "C:\Users\User\AppData\Roaming\Python\Python313\site-packages\pandas\core\internals\construction.py", line 845, in to_arrays
    content, columns = _finalize_columns_and_data(arr, columns, dtype)
                       ~~~~~~~~~~~~~~~~~~~~~~~~~~^^^^^^^^^^^^^^^^^^^^^
  File "C:\Users\User\AppData\Roaming\Python\Python313\site-packages\pandas\core\internals\construction.py", line 942, in _finalize_columns_and_data
    raise ValueError(err) from err
ValueError: 9 columns passed, passed data had 1 columns
"GET /HR_dashboard/ HTTP/1.1" 500 115092
Internal Server Error: /HR_dashboard/
Traceback (most recent call last):
  File "C:\Users\User\AppData\Roaming\Python\Python313\site-packages\pandas\core\internals\construction.py", line 939, in _finalize_columns_and_data
    columns = _validate_or_indexify_columns(contents, columns)
  File "C:\Users\User\AppData\Roaming\Python\Python313\site-packages\pandas\core\internals\construction.py", line 986, in _validate_or_indexify_columns
    raise AssertionError(
    ...<2 lines>...
    )
AssertionError: 9 columns passed, passed data had 1 columns

The above exception was the direct cause of the following exception:

Traceback (most recent call last):
  File "C:\Users\User\AppData\Roaming\Python\Python313\site-packages\django\core\handlers\exception.py", line 55, in inner
    response = get_response(request)
  File "C:\Users\User\AppData\Roaming\Python\Python313\site-packages\django\core\handlers\base.py", line 197, in _get_response
    response = wrapped_callback(request, *callback_args, **callback_kwargs)
  File "E:\Laptop Data\Cyber-Security-Awareness-Quiz\Cyber-Security-Awareness-Quiz\Sonata_Cyber_Quiz\Quiz\views.py", line 191, in HR_dashboard
    pending_df = pd.DataFrame(pending_employee_data, columns=columns)  # Convert to DataFrame
  File "C:\Users\User\AppData\Roaming\Python\Python313\site-packages\pandas\core\frame.py", line 851, in __init__
    arrays, columns, index = nested_data_to_arrays(
                             ~~~~~~~~~~~~~~~~~~~~~^
        # error: Argument 3 to "nested_data_to_arrays" has incompatible
        ^^^^^^^^^^^^^^^^^^^^^^^^^^^^^^^^^^^^^^^^^^^^^^^^^^^^^^^^^^^^^^^
    ...<4 lines>...
        dtype,
        ^^^^^^
    )
    ^
  File "C:\Users\User\AppData\Roaming\Python\Python313\site-packages\pandas\core\internals\construction.py", line 520, in nested_data_to_arrays
    arrays, columns = to_arrays(data, columns, dtype=dtype)
                      ~~~~~~~~~^^^^^^^^^^^^^^^^^^^^^^^^^^^^
  File "C:\Users\User\AppData\Roaming\Python\Python313\site-packages\pandas\core\internals\construction.py", line 845, in to_arrays
    content, columns = _finalize_columns_and_data(arr, columns, dtype)
                       ~~~~~~~~~~~~~~~~~~~~~~~~~~^^^^^^^^^^^^^^^^^^^^^
  File "C:\Users\User\AppData\Roaming\Python\Python313\site-packages\pandas\core\internals\construction.py", line 942, in _finalize_columns_and_data
    raise ValueError(err) from err
ValueError: 9 columns passed, passed data had 1 columns
"GET /HR_dashboard/ HTTP/1.1" 500 115092
Internal Server Error: /HR_dashboard/
Traceback (most recent call last):
  File "C:\Users\User\AppData\Roaming\Python\Python313\site-packages\pandas\core\internals\construction.py", line 939, in _finalize_columns_and_data
    columns = _validate_or_indexify_columns(contents, columns)
  File "C:\Users\User\AppData\Roaming\Python\Python313\site-packages\pandas\core\internals\construction.py", line 986, in _validate_or_indexify_columns
    raise AssertionError(
    ...<2 lines>...
    )
AssertionError: 9 columns passed, passed data had 1 columns

The above exception was the direct cause of the following exception:

Traceback (most recent call last):
  File "C:\Users\User\AppData\Roaming\Python\Python313\site-packages\django\core\handlers\exception.py", line 55, in inner
    response = get_response(request)
  File "C:\Users\User\AppData\Roaming\Python\Python313\site-packages\django\core\handlers\base.py", line 197, in _get_response
    response = wrapped_callback(request, *callback_args, **callback_kwargs)
  File "E:\Laptop Data\Cyber-Security-Awareness-Quiz\Cyber-Security-Awareness-Quiz\Sonata_Cyber_Quiz\Quiz\views.py", line 191, in HR_dashboard
    pending_df = pd.DataFrame(pending_employee_data, columns=columns)  # Convert to DataFrame
  File "C:\Users\User\AppData\Roaming\Python\Python313\site-packages\pandas\core\frame.py", line 851, in __init__
    arrays, columns, index = nested_data_to_arrays(
                             ~~~~~~~~~~~~~~~~~~~~~^
        # error: Argument 3 to "nested_data_to_arrays" has incompatible
        ^^^^^^^^^^^^^^^^^^^^^^^^^^^^^^^^^^^^^^^^^^^^^^^^^^^^^^^^^^^^^^^
    ...<4 lines>...
        dtype,
        ^^^^^^
    )
    ^
  File "C:\Users\User\AppData\Roaming\Python\Python313\site-packages\pandas\core\internals\construction.py", line 520, in nested_data_to_arrays
    arrays, columns = to_arrays(data, columns, dtype=dtype)
                      ~~~~~~~~~^^^^^^^^^^^^^^^^^^^^^^^^^^^^
  File "C:\Users\User\AppData\Roaming\Python\Python313\site-packages\pandas\core\internals\construction.py", line 845, in to_arrays
    content, columns = _finalize_columns_and_data(arr, columns, dtype)
                       ~~~~~~~~~~~~~~~~~~~~~~~~~~^^^^^^^^^^^^^^^^^^^^^
  File "C:\Users\User\AppData\Roaming\Python\Python313\site-packages\pandas\core\internals\construction.py", line 942, in _finalize_columns_and_data
    raise ValueError(err) from err
ValueError: 9 columns passed, passed data had 1 columns
"GET /HR_dashboard/ HTTP/1.1" 500 115216
Internal Server Error: /HR_dashboard/
Traceback (most recent call last):
  File "C:\Users\User\AppData\Roaming\Python\Python313\site-packages\pandas\core\internals\construction.py", line 939, in _finalize_columns_and_data
    columns = _validate_or_indexify_columns(contents, columns)
  File "C:\Users\User\AppData\Roaming\Python\Python313\site-packages\pandas\core\internals\construction.py", line 986, in _validate_or_indexify_columns
    raise AssertionError(
    ...<2 lines>...
    )
AssertionError: 9 columns passed, passed data had 1 columns

The above exception was the direct cause of the following exception:

Traceback (most recent call last):
  File "C:\Users\User\AppData\Roaming\Python\Python313\site-packages\django\core\handlers\exception.py", line 55, in inner
    response = get_response(request)
  File "C:\Users\User\AppData\Roaming\Python\Python313\site-packages\django\core\handlers\base.py", line 197, in _get_response
    response = wrapped_callback(request, *callback_args, **callback_kwargs)
  File "E:\Laptop Data\Cyber-Security-Awareness-Quiz\Cyber-Security-Awareness-Quiz\Sonata_Cyber_Quiz\Quiz\views.py", line 191, in HR_dashboard
    pending_df = pd.DataFrame(pending_employee_data, columns=columns)  # Convert to DataFrame
  File "C:\Users\User\AppData\Roaming\Python\Python313\site-packages\pandas\core\frame.py", line 851, in __init__
    arrays, columns, index = nested_data_to_arrays(
                             ~~~~~~~~~~~~~~~~~~~~~^
        # error: Argument 3 to "nested_data_to_arrays" has incompatible
        ^^^^^^^^^^^^^^^^^^^^^^^^^^^^^^^^^^^^^^^^^^^^^^^^^^^^^^^^^^^^^^^
    ...<4 lines>...
        dtype,
        ^^^^^^
    )
    ^
  File "C:\Users\User\AppData\Roaming\Python\Python313\site-packages\pandas\core\internals\construction.py", line 520, in nested_data_to_arrays
    arrays, columns = to_arrays(data, columns, dtype=dtype)
                      ~~~~~~~~~^^^^^^^^^^^^^^^^^^^^^^^^^^^^
  File "C:\Users\User\AppData\Roaming\Python\Python313\site-packages\pandas\core\internals\construction.py", line 845, in to_arrays
    content, columns = _finalize_columns_and_data(arr, columns, dtype)
                       ~~~~~~~~~~~~~~~~~~~~~~~~~~^^^^^^^^^^^^^^^^^^^^^
  File "C:\Users\User\AppData\Roaming\Python\Python313\site-packages\pandas\core\internals\construction.py", line 942, in _finalize_columns_and_data
    raise ValueError(err) from err
ValueError: 9 columns passed, passed data had 1 columns
"GET /HR_dashboard/ HTTP/1.1" 500 115238
Internal Server Error: /HR_dashboard/
Traceback (most recent call last):
  File "C:\Users\User\AppData\Roaming\Python\Python313\site-packages\pandas\core\internals\construction.py", line 939, in _finalize_columns_and_data
    columns = _validate_or_indexify_columns(contents, columns)
  File "C:\Users\User\AppData\Roaming\Python\Python313\site-packages\pandas\core\internals\construction.py", line 986, in _validate_or_indexify_columns
    raise AssertionError(
    ...<2 lines>...
    )
AssertionError: 9 columns passed, passed data had 1 columns

The above exception was the direct cause of the following exception:

Traceback (most recent call last):
  File "C:\Users\User\AppData\Roaming\Python\Python313\site-packages\django\core\handlers\exception.py", line 55, in inner
    response = get_response(request)
  File "C:\Users\User\AppData\Roaming\Python\Python313\site-packages\django\core\handlers\base.py", line 197, in _get_response
    response = wrapped_callback(request, *callback_args, **callback_kwargs)
  File "E:\Laptop Data\Cyber-Security-Awareness-Quiz\Cyber-Security-Awareness-Quiz\Sonata_Cyber_Quiz\Quiz\views.py", line 192, in HR_dashboard
    pending_df = pd.DataFrame(pending_employee_data, columns=columns)  # Convert to DataFrame
  File "C:\Users\User\AppData\Roaming\Python\Python313\site-packages\pandas\core\frame.py", line 851, in __init__
    arrays, columns, index = nested_data_to_arrays(
                             ~~~~~~~~~~~~~~~~~~~~~^
        # error: Argument 3 to "nested_data_to_arrays" has incompatible
        ^^^^^^^^^^^^^^^^^^^^^^^^^^^^^^^^^^^^^^^^^^^^^^^^^^^^^^^^^^^^^^^
    ...<4 lines>...
        dtype,
        ^^^^^^
    )
    ^
  File "C:\Users\User\AppData\Roaming\Python\Python313\site-packages\pandas\core\internals\construction.py", line 520, in nested_data_to_arrays
    arrays, columns = to_arrays(data, columns, dtype=dtype)
                      ~~~~~~~~~^^^^^^^^^^^^^^^^^^^^^^^^^^^^
  File "C:\Users\User\AppData\Roaming\Python\Python313\site-packages\pandas\core\internals\construction.py", line 845, in to_arrays
    content, columns = _finalize_columns_and_data(arr, columns, dtype)
                       ~~~~~~~~~~~~~~~~~~~~~~~~~~^^^^^^^^^^^^^^^^^^^^^
  File "C:\Users\User\AppData\Roaming\Python\Python313\site-packages\pandas\core\internals\construction.py", line 942, in _finalize_columns_and_data
    raise ValueError(err) from err
ValueError: 9 columns passed, passed data had 1 columns
"GET /HR_dashboard/ HTTP/1.1" 500 115079
Internal Server Error: /HR_dashboard/
Traceback (most recent call last):
  File "C:\Users\User\AppData\Roaming\Python\Python313\site-packages\django\core\handlers\exception.py", line 55, in inner
    response = get_response(request)
  File "C:\Users\User\AppData\Roaming\Python\Python313\site-packages\django\core\handlers\base.py", line 197, in _get_response
    response = wrapped_callback(request, *callback_args, **callback_kwargs)
  File "E:\Laptop Data\Cyber-Security-Awareness-Quiz\Cyber-Security-Awareness-Quiz\Sonata_Cyber_Quiz\Quiz\views.py", line 211, in HR_dashboard
    return render(request, 'KYC.html', {'employee_details': employee_details, 'completed_employee_details': completed_employee_details,
                                        'reject_employee_details': reject_employee_details,'hr_employee': hr_employee,'hr_employee_id': hr_employee_id,
                                        'employee_unitname': employee_unitname,'pending_employee_count': pending_employee_count})
  File "C:\Users\User\AppData\Roaming\Python\Python313\site-packages\django\shortcuts.py", line 24, in render
    content = loader.render_to_string(template_name, context, request, using=using)
  File "C:\Users\User\AppData\Roaming\Python\Python313\site-packages\django\template\loader.py", line 61, in render_to_string
    template = get_template(template_name, using=using)
  File "C:\Users\User\AppData\Roaming\Python\Python313\site-packages\django\template\loader.py", line 15, in get_template
    return engine.get_template(template_name)
           ~~~~~~~~~~~~~~~~~~~^^^^^^^^^^^^^^^
  File "C:\Users\User\AppData\Roaming\Python\Python313\site-packages\django\template\backends\django.py", line 33, in get_template
    return Template(self.engine.get_template(template_name), self)
                    ~~~~~~~~~~~~~~~~~~~~~~~~^^^^^^^^^^^^^^^
  File "C:\Users\User\AppData\Roaming\Python\Python313\site-packages\django\template\engine.py", line 175, in get_template
    template, origin = self.find_template(template_name)
                       ~~~~~~~~~~~~~~~~~~^^^^^^^^^^^^^^^
  File "C:\Users\User\AppData\Roaming\Python\Python313\site-packages\django\template\engine.py", line 157, in find_template
    template = loader.get_template(name, skip=skip)
  File "C:\Users\User\AppData\Roaming\Python\Python313\site-packages\django\template\loaders\cached.py", line 57, in get_template
    template = super().get_template(template_name, skip)
  File "C:\Users\User\AppData\Roaming\Python\Python313\site-packages\django\template\loaders\base.py", line 28, in get_template
    return Template(
        contents,
    ...<2 lines>...
        self.engine,
    )
  File "C:\Users\User\AppData\Roaming\Python\Python313\site-packages\django\template\base.py", line 154, in __init__
    self.nodelist = self.compile_nodelist()
                    ~~~~~~~~~~~~~~~~~~~~~^^
  File "C:\Users\User\AppData\Roaming\Python\Python313\site-packages\django\template\base.py", line 200, in compile_nodelist
    return parser.parse()
           ~~~~~~~~~~~~^^
  File "C:\Users\User\AppData\Roaming\Python\Python313\site-packages\django\template\base.py", line 513, in parse
    raise self.error(token, e)
  File "C:\Users\User\AppData\Roaming\Python\Python313\site-packages\django\template\base.py", line 511, in parse
    compiled_result = compile_func(self, token)
  File "C:\Users\User\AppData\Roaming\Python\Python313\site-packages\django\template\defaulttags.py", line 853, in do_for
    nodelist_loop = parser.parse(
        (
    ...<2 lines>...
        )
    )
  File "C:\Users\User\AppData\Roaming\Python\Python313\site-packages\django\template\base.py", line 484, in parse
    raise self.error(token, e)
  File "C:\Users\User\AppData\Roaming\Python\Python313\site-packages\django\template\base.py", line 482, in parse
    filter_expression = self.compile_filter(token.contents)
  File "C:\Users\User\AppData\Roaming\Python\Python313\site-packages\django\template\base.py", line 600, in compile_filter
    return FilterExpression(token, self)
  File "C:\Users\User\AppData\Roaming\Python\Python313\site-packages\django\template\base.py", line 698, in __init__
    filter_func = parser.find_filter(filter_name)
  File "C:\Users\User\AppData\Roaming\Python\Python313\site-packages\django\template\base.py", line 606, in find_filter
    raise TemplateSyntaxError("Invalid filter: '%s'" % filter_name)
django.template.exceptions.TemplateSyntaxError: Invalid filter: 'localtime'
"GET /HR_dashboard/ HTTP/1.1" 500 1427
Internal Server Error: /HR_dashboard/
Traceback (most recent call last):
  File "C:\Users\User\AppData\Roaming\Python\Python313\site-packages\django\core\handlers\exception.py", line 55, in inner
    response = get_response(request)
  File "C:\Users\User\AppData\Roaming\Python\Python313\site-packages\django\core\handlers\base.py", line 197, in _get_response
    response = wrapped_callback(request, *callback_args, **callback_kwargs)
  File "E:\Laptop Data\Cyber-Security-Awareness-Quiz\Cyber-Security-Awareness-Quiz\Sonata_Cyber_Quiz\Quiz\views.py", line 211, in HR_dashboard
    return render(request, 'KYC.html', {'employee_details': employee_details, 'completed_employee_details': completed_employee_details,
                                        'reject_employee_details': reject_employee_details,'hr_employee': hr_employee,'hr_employee_id': hr_employee_id,
                                        'employee_unitname': employee_unitname,'pending_employee_count': pending_employee_count})
  File "C:\Users\User\AppData\Roaming\Python\Python313\site-packages\django\shortcuts.py", line 24, in render
    content = loader.render_to_string(template_name, context, request, using=using)
  File "C:\Users\User\AppData\Roaming\Python\Python313\site-packages\django\template\loader.py", line 61, in render_to_string
    template = get_template(template_name, using=using)
  File "C:\Users\User\AppData\Roaming\Python\Python313\site-packages\django\template\loader.py", line 15, in get_template
    return engine.get_template(template_name)
           ~~~~~~~~~~~~~~~~~~~^^^^^^^^^^^^^^^
  File "C:\Users\User\AppData\Roaming\Python\Python313\site-packages\django\template\backends\django.py", line 33, in get_template
    return Template(self.engine.get_template(template_name), self)
                    ~~~~~~~~~~~~~~~~~~~~~~~~^^^^^^^^^^^^^^^
  File "C:\Users\User\AppData\Roaming\Python\Python313\site-packages\django\template\engine.py", line 175, in get_template
    template, origin = self.find_template(template_name)
                       ~~~~~~~~~~~~~~~~~~^^^^^^^^^^^^^^^
  File "C:\Users\User\AppData\Roaming\Python\Python313\site-packages\django\template\engine.py", line 157, in find_template
    template = loader.get_template(name, skip=skip)
  File "C:\Users\User\AppData\Roaming\Python\Python313\site-packages\django\template\loaders\cached.py", line 57, in get_template
    template = super().get_template(template_name, skip)
  File "C:\Users\User\AppData\Roaming\Python\Python313\site-packages\django\template\loaders\base.py", line 28, in get_template
    return Template(
        contents,
    ...<2 lines>...
        self.engine,
    )
  File "C:\Users\User\AppData\Roaming\Python\Python313\site-packages\django\template\base.py", line 154, in __init__
    self.nodelist = self.compile_nodelist()
                    ~~~~~~~~~~~~~~~~~~~~~^^
  File "C:\Users\User\AppData\Roaming\Python\Python313\site-packages\django\template\base.py", line 200, in compile_nodelist
    return parser.parse()
           ~~~~~~~~~~~~^^
  File "C:\Users\User\AppData\Roaming\Python\Python313\site-packages\django\template\base.py", line 513, in parse
    raise self.error(token, e)
  File "C:\Users\User\AppData\Roaming\Python\Python313\site-packages\django\template\base.py", line 511, in parse
    compiled_result = compile_func(self, token)
  File "C:\Users\User\AppData\Roaming\Python\Python313\site-packages\django\template\defaulttags.py", line 853, in do_for
    nodelist_loop = parser.parse(
        (
    ...<2 lines>...
        )
    )
  File "C:\Users\User\AppData\Roaming\Python\Python313\site-packages\django\template\base.py", line 484, in parse
    raise self.error(token, e)
  File "C:\Users\User\AppData\Roaming\Python\Python313\site-packages\django\template\base.py", line 482, in parse
    filter_expression = self.compile_filter(token.contents)
  File "C:\Users\User\AppData\Roaming\Python\Python313\site-packages\django\template\base.py", line 600, in compile_filter
    return FilterExpression(token, self)
  File "C:\Users\User\AppData\Roaming\Python\Python313\site-packages\django\template\base.py", line 698, in __init__
    filter_func = parser.find_filter(filter_name)
  File "C:\Users\User\AppData\Roaming\Python\Python313\site-packages\django\template\base.py", line 606, in find_filter
    raise TemplateSyntaxError("Invalid filter: '%s'" % filter_name)
django.template.exceptions.TemplateSyntaxError: Invalid filter: 'localtime'
"GET /HR_dashboard/ HTTP/1.1" 500 1427
Internal Server Error: /HR_dashboard/
Traceback (most recent call last):
  File "C:\Users\User\AppData\Roaming\Python\Python313\site-packages\django\core\handlers\exception.py", line 55, in inner
    response = get_response(request)
  File "C:\Users\User\AppData\Roaming\Python\Python313\site-packages\django\core\handlers\base.py", line 197, in _get_response
    response = wrapped_callback(request, *callback_args, **callback_kwargs)
  File "E:\Laptop Data\Cyber-Security-Awareness-Quiz\Cyber-Security-Awareness-Quiz\Sonata_Cyber_Quiz\Quiz\views.py", line 211, in HR_dashboard
    return render(request, 'KYC.html', {'employee_details': employee_details, 'completed_employee_details': completed_employee_details,
                                        'reject_employee_details': reject_employee_details,'hr_employee': hr_employee,'hr_employee_id': hr_employee_id,
                                        'employee_unitname': employee_unitname,'pending_employee_count': pending_employee_count})
  File "C:\Users\User\AppData\Roaming\Python\Python313\site-packages\django\shortcuts.py", line 24, in render
    content = loader.render_to_string(template_name, context, request, using=using)
  File "C:\Users\User\AppData\Roaming\Python\Python313\site-packages\django\template\loader.py", line 61, in render_to_string
    template = get_template(template_name, using=using)
  File "C:\Users\User\AppData\Roaming\Python\Python313\site-packages\django\template\loader.py", line 15, in get_template
    return engine.get_template(template_name)
           ~~~~~~~~~~~~~~~~~~~^^^^^^^^^^^^^^^
  File "C:\Users\User\AppData\Roaming\Python\Python313\site-packages\django\template\backends\django.py", line 33, in get_template
    return Template(self.engine.get_template(template_name), self)
                    ~~~~~~~~~~~~~~~~~~~~~~~~^^^^^^^^^^^^^^^
  File "C:\Users\User\AppData\Roaming\Python\Python313\site-packages\django\template\engine.py", line 175, in get_template
    template, origin = self.find_template(template_name)
                       ~~~~~~~~~~~~~~~~~~^^^^^^^^^^^^^^^
  File "C:\Users\User\AppData\Roaming\Python\Python313\site-packages\django\template\engine.py", line 157, in find_template
    template = loader.get_template(name, skip=skip)
  File "C:\Users\User\AppData\Roaming\Python\Python313\site-packages\django\template\loaders\cached.py", line 57, in get_template
    template = super().get_template(template_name, skip)
  File "C:\Users\User\AppData\Roaming\Python\Python313\site-packages\django\template\loaders\base.py", line 28, in get_template
    return Template(
        contents,
    ...<2 lines>...
        self.engine,
    )
  File "C:\Users\User\AppData\Roaming\Python\Python313\site-packages\django\template\base.py", line 154, in __init__
    self.nodelist = self.compile_nodelist()
                    ~~~~~~~~~~~~~~~~~~~~~^^
  File "C:\Users\User\AppData\Roaming\Python\Python313\site-packages\django\template\base.py", line 200, in compile_nodelist
    return parser.parse()
           ~~~~~~~~~~~~^^
  File "C:\Users\User\AppData\Roaming\Python\Python313\site-packages\django\template\base.py", line 513, in parse
    raise self.error(token, e)
  File "C:\Users\User\AppData\Roaming\Python\Python313\site-packages\django\template\base.py", line 511, in parse
    compiled_result = compile_func(self, token)
  File "C:\Users\User\AppData\Roaming\Python\Python313\site-packages\django\template\defaulttags.py", line 853, in do_for
    nodelist_loop = parser.parse(
        (
    ...<2 lines>...
        )
    )
  File "C:\Users\User\AppData\Roaming\Python\Python313\site-packages\django\template\base.py", line 484, in parse
    raise self.error(token, e)
  File "C:\Users\User\AppData\Roaming\Python\Python313\site-packages\django\template\base.py", line 482, in parse
    filter_expression = self.compile_filter(token.contents)
  File "C:\Users\User\AppData\Roaming\Python\Python313\site-packages\django\template\base.py", line 600, in compile_filter
    return FilterExpression(token, self)
  File "C:\Users\User\AppData\Roaming\Python\Python313\site-packages\django\template\base.py", line 698, in __init__
    filter_func = parser.find_filter(filter_name)
  File "C:\Users\User\AppData\Roaming\Python\Python313\site-packages\django\template\base.py", line 606, in find_filter
    raise TemplateSyntaxError("Invalid filter: '%s'" % filter_name)
django.template.exceptions.TemplateSyntaxError: Invalid filter: 'localtime'
"GET /HR_dashboard/ HTTP/1.1" 500 288174
Internal Server Error: /HR_dashboard/
Traceback (most recent call last):
  File "C:\Users\User\AppData\Roaming\Python\Python313\site-packages\django\core\handlers\exception.py", line 55, in inner
    response = get_response(request)
  File "C:\Users\User\AppData\Roaming\Python\Python313\site-packages\django\core\handlers\base.py", line 197, in _get_response
    response = wrapped_callback(request, *callback_args, **callback_kwargs)
  File "E:\Laptop Data\Cyber-Security-Awareness-Quiz\Cyber-Security-Awareness-Quiz\Sonata_Cyber_Quiz\Quiz\views.py", line 211, in HR_dashboard
    return render(request, 'KYC.html', {'employee_details': employee_details, 'completed_employee_details': completed_employee_details,
                                        'reject_employee_details': reject_employee_details,'hr_employee': hr_employee,'hr_employee_id': hr_employee_id,
                                        'employee_unitname': employee_unitname,'pending_employee_count': pending_employee_count})
  File "C:\Users\User\AppData\Roaming\Python\Python313\site-packages\django\shortcuts.py", line 24, in render
    content = loader.render_to_string(template_name, context, request, using=using)
  File "C:\Users\User\AppData\Roaming\Python\Python313\site-packages\django\template\loader.py", line 61, in render_to_string
    template = get_template(template_name, using=using)
  File "C:\Users\User\AppData\Roaming\Python\Python313\site-packages\django\template\loader.py", line 15, in get_template
    return engine.get_template(template_name)
           ~~~~~~~~~~~~~~~~~~~^^^^^^^^^^^^^^^
  File "C:\Users\User\AppData\Roaming\Python\Python313\site-packages\django\template\backends\django.py", line 33, in get_template
    return Template(self.engine.get_template(template_name), self)
                    ~~~~~~~~~~~~~~~~~~~~~~~~^^^^^^^^^^^^^^^
  File "C:\Users\User\AppData\Roaming\Python\Python313\site-packages\django\template\engine.py", line 175, in get_template
    template, origin = self.find_template(template_name)
                       ~~~~~~~~~~~~~~~~~~^^^^^^^^^^^^^^^
  File "C:\Users\User\AppData\Roaming\Python\Python313\site-packages\django\template\engine.py", line 157, in find_template
    template = loader.get_template(name, skip=skip)
  File "C:\Users\User\AppData\Roaming\Python\Python313\site-packages\django\template\loaders\cached.py", line 57, in get_template
    template = super().get_template(template_name, skip)
  File "C:\Users\User\AppData\Roaming\Python\Python313\site-packages\django\template\loaders\base.py", line 28, in get_template
    return Template(
        contents,
    ...<2 lines>...
        self.engine,
    )
  File "C:\Users\User\AppData\Roaming\Python\Python313\site-packages\django\template\base.py", line 154, in __init__
    self.nodelist = self.compile_nodelist()
                    ~~~~~~~~~~~~~~~~~~~~~^^
  File "C:\Users\User\AppData\Roaming\Python\Python313\site-packages\django\template\base.py", line 200, in compile_nodelist
    return parser.parse()
           ~~~~~~~~~~~~^^
  File "C:\Users\User\AppData\Roaming\Python\Python313\site-packages\django\template\base.py", line 513, in parse
    raise self.error(token, e)
  File "C:\Users\User\AppData\Roaming\Python\Python313\site-packages\django\template\base.py", line 511, in parse
    compiled_result = compile_func(self, token)
  File "C:\Users\User\AppData\Roaming\Python\Python313\site-packages\django\template\defaulttags.py", line 853, in do_for
    nodelist_loop = parser.parse(
        (
    ...<2 lines>...
        )
    )
  File "C:\Users\User\AppData\Roaming\Python\Python313\site-packages\django\template\base.py", line 484, in parse
    raise self.error(token, e)
  File "C:\Users\User\AppData\Roaming\Python\Python313\site-packages\django\template\base.py", line 482, in parse
    filter_expression = self.compile_filter(token.contents)
  File "C:\Users\User\AppData\Roaming\Python\Python313\site-packages\django\template\base.py", line 600, in compile_filter
    return FilterExpression(token, self)
  File "C:\Users\User\AppData\Roaming\Python\Python313\site-packages\django\template\base.py", line 703, in __init__
    raise TemplateSyntaxError(
    ...<2 lines>...
    )
django.template.exceptions.TemplateSyntaxError: Could not parse the remainder: '{% localtime on %}{{ emp.Verified_Date' from '{% localtime on %}{{ emp.Verified_Date'
"GET /HR_dashboard/ HTTP/1.1" 500 283033
Internal Server Error: /HR_dashboard/
Traceback (most recent call last):
  File "C:\Users\User\AppData\Roaming\Python\Python313\site-packages\django\core\handlers\exception.py", line 55, in inner
    response = get_response(request)
  File "C:\Users\User\AppData\Roaming\Python\Python313\site-packages\django\core\handlers\base.py", line 197, in _get_response
    response = wrapped_callback(request, *callback_args, **callback_kwargs)
  File "E:\Laptop Data\Cyber-Security-Awareness-Quiz\Cyber-Security-Awareness-Quiz\Sonata_Cyber_Quiz\Quiz\views.py", line 207, in HR_dashboard
    Verified_Date = localtime(reject_employee_details.Verified_Date)
                              ^^^^^^^^^^^^^^^^^^^^^^^^^^^^^^^^^^^^^
AttributeError: 'list' object has no attribute 'Verified_Date'
"GET /HR_dashboard/ HTTP/1.1" 500 149379
Internal Server Error: /HR_dashboard/
Traceback (most recent call last):
  File "C:\Users\User\AppData\Roaming\Python\Python313\site-packages\django\core\handlers\exception.py", line 55, in inner
    response = get_response(request)
  File "C:\Users\User\AppData\Roaming\Python\Python313\site-packages\django\core\handlers\base.py", line 197, in _get_response
    response = wrapped_callback(request, *callback_args, **callback_kwargs)
  File "E:\Laptop Data\Cyber-Security-Awareness-Quiz\Cyber-Security-Awareness-Quiz\Sonata_Cyber_Quiz\Quiz\views.py", line 207, in HR_dashboard
    Verified_Date = localtime(reject_employee_details.Verified_Date)
                              ^^^^^^^^^^^^^^^^^^^^^^^^^^^^^^^^^^^^^
AttributeError: 'list' object has no attribute 'Verified_Date'
"GET /HR_dashboard/ HTTP/1.1" 500 149379
Internal Server Error: /HR_dashboard/
Traceback (most recent call last):
  File "C:\Users\User\AppData\Roaming\Python\Python313\site-packages\django\core\handlers\exception.py", line 55, in inner
    response = get_response(request)
  File "C:\Users\User\AppData\Roaming\Python\Python313\site-packages\django\core\handlers\base.py", line 197, in _get_response
    response = wrapped_callback(request, *callback_args, **callback_kwargs)
  File "E:\Laptop Data\Cyber-Security-Awareness-Quiz\Cyber-Security-Awareness-Quiz\Sonata_Cyber_Quiz\Quiz\views.py", line 207, in HR_dashboard
    Verified_Date = localtime(reject_employee_details.Verified_Date)
                              ^^^^^^^^^^^^^^^^^^^^^^^^^^^^^^^^^^^^^
AttributeError: 'list' object has no attribute 'Verified_Date'
"GET /HR_dashboard/ HTTP/1.1" 500 149379
Internal Server Error: /HR_dashboard/
Traceback (most recent call last):
  File "C:\Users\User\AppData\Roaming\Python\Python313\site-packages\django\core\handlers\exception.py", line 55, in inner
    response = get_response(request)
  File "C:\Users\User\AppData\Roaming\Python\Python313\site-packages\django\core\handlers\base.py", line 197, in _get_response
    response = wrapped_callback(request, *callback_args, **callback_kwargs)
  File "E:\Laptop Data\Cyber-Security-Awareness-Quiz\Cyber-Security-Awareness-Quiz\Sonata_Cyber_Quiz\Quiz\views.py", line 208, in HR_dashboard
    Verified_Date = localtime(reject_employee_details.Verified_Date)
                              ^^^^^^^^^^^^^^^^^^^^^^^^^^^^^^^^^^^^^
AttributeError: 'list' object has no attribute 'Verified_Date'
"GET /HR_dashboard/ HTTP/1.1" 500 149310
Internal Server Error: /HR_dashboard/
Traceback (most recent call last):
  File "C:\Users\User\AppData\Roaming\Python\Python313\site-packages\django\core\handlers\exception.py", line 55, in inner
    response = get_response(request)
  File "C:\Users\User\AppData\Roaming\Python\Python313\site-packages\django\core\handlers\base.py", line 197, in _get_response
    response = wrapped_callback(request, *callback_args, **callback_kwargs)
  File "E:\Laptop Data\Cyber-Security-Awareness-Quiz\Cyber-Security-Awareness-Quiz\Sonata_Cyber_Quiz\Quiz\views.py", line 208, in HR_dashboard
    Verified_Date = localtime(reject_employee_details.Verified_Date)
                              ^^^^^^^^^^^^^^^^^^^^^^^^^^^^^^^^^^^^^
AttributeError: 'list' object has no attribute 'Verified_Date'
"GET /HR_dashboard/ HTTP/1.1" 500 149447
Internal Server Error: /HR_dashboard/
Traceback (most recent call last):
  File "C:\Users\User\AppData\Roaming\Python\Python313\site-packages\pandas\core\internals\construction.py", line 939, in _finalize_columns_and_data
    columns = _validate_or_indexify_columns(contents, columns)
  File "C:\Users\User\AppData\Roaming\Python\Python313\site-packages\pandas\core\internals\construction.py", line 986, in _validate_or_indexify_columns
    raise AssertionError(
    ...<2 lines>...
    )
AssertionError: 10 columns passed, passed data had 9 columns

The above exception was the direct cause of the following exception:

Traceback (most recent call last):
  File "C:\Users\User\AppData\Roaming\Python\Python313\site-packages\django\core\handlers\exception.py", line 55, in inner
    response = get_response(request)
  File "C:\Users\User\AppData\Roaming\Python\Python313\site-packages\django\core\handlers\base.py", line 197, in _get_response
    response = wrapped_callback(request, *callback_args, **callback_kwargs)
  File "E:\Laptop Data\Cyber-Security-Awareness-Quiz\Cyber-Security-Awareness-Quiz\Sonata_Cyber_Quiz\Quiz\views.py", line 198, in HR_dashboard
    df = pd.DataFrame(employee_data, columns=columns)  # Convert to DataFrame
  File "C:\Users\User\AppData\Roaming\Python\Python313\site-packages\pandas\core\frame.py", line 851, in __init__
    arrays, columns, index = nested_data_to_arrays(
                             ~~~~~~~~~~~~~~~~~~~~~^
        # error: Argument 3 to "nested_data_to_arrays" has incompatible
        ^^^^^^^^^^^^^^^^^^^^^^^^^^^^^^^^^^^^^^^^^^^^^^^^^^^^^^^^^^^^^^^
    ...<4 lines>...
        dtype,
        ^^^^^^
    )
    ^
  File "C:\Users\User\AppData\Roaming\Python\Python313\site-packages\pandas\core\internals\construction.py", line 520, in nested_data_to_arrays
    arrays, columns = to_arrays(data, columns, dtype=dtype)
                      ~~~~~~~~~^^^^^^^^^^^^^^^^^^^^^^^^^^^^
  File "C:\Users\User\AppData\Roaming\Python\Python313\site-packages\pandas\core\internals\construction.py", line 845, in to_arrays
    content, columns = _finalize_columns_and_data(arr, columns, dtype)
                       ~~~~~~~~~~~~~~~~~~~~~~~~~~^^^^^^^^^^^^^^^^^^^^^
  File "C:\Users\User\AppData\Roaming\Python\Python313\site-packages\pandas\core\internals\construction.py", line 942, in _finalize_columns_and_data
    raise ValueError(err) from err
ValueError: 10 columns passed, passed data had 9 columns
"GET /HR_dashboard/ HTTP/1.1" 500 184685
Internal Server Error: /HR_dashboard/
Traceback (most recent call last):
  File "C:\Users\User\AppData\Roaming\Python\Python313\site-packages\pandas\core\internals\construction.py", line 939, in _finalize_columns_and_data
    columns = _validate_or_indexify_columns(contents, columns)
  File "C:\Users\User\AppData\Roaming\Python\Python313\site-packages\pandas\core\internals\construction.py", line 986, in _validate_or_indexify_columns
    raise AssertionError(
    ...<2 lines>...
    )
AssertionError: 10 columns passed, passed data had 9 columns

The above exception was the direct cause of the following exception:

Traceback (most recent call last):
  File "C:\Users\User\AppData\Roaming\Python\Python313\site-packages\django\core\handlers\exception.py", line 55, in inner
    response = get_response(request)
  File "C:\Users\User\AppData\Roaming\Python\Python313\site-packages\django\core\handlers\base.py", line 197, in _get_response
    response = wrapped_callback(request, *callback_args, **callback_kwargs)
  File "E:\Laptop Data\Cyber-Security-Awareness-Quiz\Cyber-Security-Awareness-Quiz\Sonata_Cyber_Quiz\Quiz\views.py", line 198, in HR_dashboard
    df = pd.DataFrame(employee_data, columns=columns)  # Convert to DataFrame
  File "C:\Users\User\AppData\Roaming\Python\Python313\site-packages\pandas\core\frame.py", line 851, in __init__
    arrays, columns, index = nested_data_to_arrays(
                             ~~~~~~~~~~~~~~~~~~~~~^
        # error: Argument 3 to "nested_data_to_arrays" has incompatible
        ^^^^^^^^^^^^^^^^^^^^^^^^^^^^^^^^^^^^^^^^^^^^^^^^^^^^^^^^^^^^^^^
    ...<4 lines>...
        dtype,
        ^^^^^^
    )
    ^
  File "C:\Users\User\AppData\Roaming\Python\Python313\site-packages\pandas\core\internals\construction.py", line 520, in nested_data_to_arrays
    arrays, columns = to_arrays(data, columns, dtype=dtype)
                      ~~~~~~~~~^^^^^^^^^^^^^^^^^^^^^^^^^^^^
  File "C:\Users\User\AppData\Roaming\Python\Python313\site-packages\pandas\core\internals\construction.py", line 845, in to_arrays
    content, columns = _finalize_columns_and_data(arr, columns, dtype)
                       ~~~~~~~~~~~~~~~~~~~~~~~~~~^^^^^^^^^^^^^^^^^^^^^
  File "C:\Users\User\AppData\Roaming\Python\Python313\site-packages\pandas\core\internals\construction.py", line 942, in _finalize_columns_and_data
    raise ValueError(err) from err
ValueError: 10 columns passed, passed data had 9 columns
"GET /HR_dashboard/ HTTP/1.1" 500 184822
Internal Server Error: /HR_dashboard/
Traceback (most recent call last):
  File "C:\Users\User\AppData\Roaming\Python\Python313\site-packages\pandas\core\internals\construction.py", line 939, in _finalize_columns_and_data
    columns = _validate_or_indexify_columns(contents, columns)
  File "C:\Users\User\AppData\Roaming\Python\Python313\site-packages\pandas\core\internals\construction.py", line 986, in _validate_or_indexify_columns
    raise AssertionError(
    ...<2 lines>...
    )
AssertionError: 10 columns passed, passed data had 9 columns

The above exception was the direct cause of the following exception:

Traceback (most recent call last):
  File "C:\Users\User\AppData\Roaming\Python\Python313\site-packages\django\core\handlers\exception.py", line 55, in inner
    response = get_response(request)
  File "C:\Users\User\AppData\Roaming\Python\Python313\site-packages\django\core\handlers\base.py", line 197, in _get_response
    response = wrapped_callback(request, *callback_args, **callback_kwargs)
  File "E:\Laptop Data\Cyber-Security-Awareness-Quiz\Cyber-Security-Awareness-Quiz\Sonata_Cyber_Quiz\Quiz\views.py", line 219, in HR_dashboard
    df = pd.DataFrame(employee_data, columns=columns)  # Convert to DataFrame
  File "C:\Users\User\AppData\Roaming\Python\Python313\site-packages\pandas\core\frame.py", line 851, in __init__
    arrays, columns, index = nested_data_to_arrays(
                             ~~~~~~~~~~~~~~~~~~~~~^
        # error: Argument 3 to "nested_data_to_arrays" has incompatible
        ^^^^^^^^^^^^^^^^^^^^^^^^^^^^^^^^^^^^^^^^^^^^^^^^^^^^^^^^^^^^^^^
    ...<4 lines>...
        dtype,
        ^^^^^^
    )
    ^
  File "C:\Users\User\AppData\Roaming\Python\Python313\site-packages\pandas\core\internals\construction.py", line 520, in nested_data_to_arrays
    arrays, columns = to_arrays(data, columns, dtype=dtype)
                      ~~~~~~~~~^^^^^^^^^^^^^^^^^^^^^^^^^^^^
  File "C:\Users\User\AppData\Roaming\Python\Python313\site-packages\pandas\core\internals\construction.py", line 845, in to_arrays
    content, columns = _finalize_columns_and_data(arr, columns, dtype)
                       ~~~~~~~~~~~~~~~~~~~~~~~~~~^^^^^^^^^^^^^^^^^^^^^
  File "C:\Users\User\AppData\Roaming\Python\Python313\site-packages\pandas\core\internals\construction.py", line 942, in _finalize_columns_and_data
    raise ValueError(err) from err
ValueError: 10 columns passed, passed data had 9 columns
"GET /HR_dashboard/ HTTP/1.1" 500 184777
Internal Server Error: /HR_dashboard/
Traceback (most recent call last):
  File "C:\Users\User\AppData\Roaming\Python\Python313\site-packages\pandas\core\internals\construction.py", line 939, in _finalize_columns_and_data
    columns = _validate_or_indexify_columns(contents, columns)
  File "C:\Users\User\AppData\Roaming\Python\Python313\site-packages\pandas\core\internals\construction.py", line 986, in _validate_or_indexify_columns
    raise AssertionError(
    ...<2 lines>...
    )
AssertionError: 10 columns passed, passed data had 9 columns

The above exception was the direct cause of the following exception:

Traceback (most recent call last):
  File "C:\Users\User\AppData\Roaming\Python\Python313\site-packages\django\core\handlers\exception.py", line 55, in inner
    response = get_response(request)
  File "C:\Users\User\AppData\Roaming\Python\Python313\site-packages\django\core\handlers\base.py", line 197, in _get_response
    response = wrapped_callback(request, *callback_args, **callback_kwargs)
  File "E:\Laptop Data\Cyber-Security-Awareness-Quiz\Cyber-Security-Awareness-Quiz\Sonata_Cyber_Quiz\Quiz\views.py", line 219, in HR_dashboard
    df = pd.DataFrame(employee_data, columns=columns)  # Convert to DataFrame
  File "C:\Users\User\AppData\Roaming\Python\Python313\site-packages\pandas\core\frame.py", line 851, in __init__
    arrays, columns, index = nested_data_to_arrays(
                             ~~~~~~~~~~~~~~~~~~~~~^
        # error: Argument 3 to "nested_data_to_arrays" has incompatible
        ^^^^^^^^^^^^^^^^^^^^^^^^^^^^^^^^^^^^^^^^^^^^^^^^^^^^^^^^^^^^^^^
    ...<4 lines>...
        dtype,
        ^^^^^^
    )
    ^
  File "C:\Users\User\AppData\Roaming\Python\Python313\site-packages\pandas\core\internals\construction.py", line 520, in nested_data_to_arrays
    arrays, columns = to_arrays(data, columns, dtype=dtype)
                      ~~~~~~~~~^^^^^^^^^^^^^^^^^^^^^^^^^^^^
  File "C:\Users\User\AppData\Roaming\Python\Python313\site-packages\pandas\core\internals\construction.py", line 845, in to_arrays
    content, columns = _finalize_columns_and_data(arr, columns, dtype)
                       ~~~~~~~~~~~~~~~~~~~~~~~~~~^^^^^^^^^^^^^^^^^^^^^
  File "C:\Users\User\AppData\Roaming\Python\Python313\site-packages\pandas\core\internals\construction.py", line 942, in _finalize_columns_and_data
    raise ValueError(err) from err
ValueError: 10 columns passed, passed data had 9 columns
"GET /HR_dashboard/ HTTP/1.1" 500 184777
Internal Server Error: /HR_dashboard/
Traceback (most recent call last):
  File "C:\Users\User\AppData\Roaming\Python\Python313\site-packages\pandas\core\internals\construction.py", line 939, in _finalize_columns_and_data
    columns = _validate_or_indexify_columns(contents, columns)
  File "C:\Users\User\AppData\Roaming\Python\Python313\site-packages\pandas\core\internals\construction.py", line 986, in _validate_or_indexify_columns
    raise AssertionError(
    ...<2 lines>...
    )
AssertionError: 9 columns passed, passed data had 8 columns

The above exception was the direct cause of the following exception:

Traceback (most recent call last):
  File "C:\Users\User\AppData\Roaming\Python\Python313\site-packages\django\core\handlers\exception.py", line 55, in inner
    response = get_response(request)
  File "C:\Users\User\AppData\Roaming\Python\Python313\site-packages\django\core\handlers\base.py", line 197, in _get_response
    response = wrapped_callback(request, *callback_args, **callback_kwargs)
  File "E:\Laptop Data\Cyber-Security-Awareness-Quiz\Cyber-Security-Awareness-Quiz\Sonata_Cyber_Quiz\Quiz\views.py", line 218, in HR_dashboard
    df = pd.DataFrame(employee_data, columns=columns)  # Convert to DataFrame
  File "C:\Users\User\AppData\Roaming\Python\Python313\site-packages\pandas\core\frame.py", line 851, in __init__
    arrays, columns, index = nested_data_to_arrays(
                             ~~~~~~~~~~~~~~~~~~~~~^
        # error: Argument 3 to "nested_data_to_arrays" has incompatible
        ^^^^^^^^^^^^^^^^^^^^^^^^^^^^^^^^^^^^^^^^^^^^^^^^^^^^^^^^^^^^^^^
    ...<4 lines>...
        dtype,
        ^^^^^^
    )
    ^
  File "C:\Users\User\AppData\Roaming\Python\Python313\site-packages\pandas\core\internals\construction.py", line 520, in nested_data_to_arrays
    arrays, columns = to_arrays(data, columns, dtype=dtype)
                      ~~~~~~~~~^^^^^^^^^^^^^^^^^^^^^^^^^^^^
  File "C:\Users\User\AppData\Roaming\Python\Python313\site-packages\pandas\core\internals\construction.py", line 845, in to_arrays
    content, columns = _finalize_columns_and_data(arr, columns, dtype)
                       ~~~~~~~~~~~~~~~~~~~~~~~~~~^^^^^^^^^^^^^^^^^^^^^
  File "C:\Users\User\AppData\Roaming\Python\Python313\site-packages\pandas\core\internals\construction.py", line 942, in _finalize_columns_and_data
    raise ValueError(err) from err
ValueError: 9 columns passed, passed data had 8 columns
"GET /HR_dashboard/ HTTP/1.1" 500 180637
Internal Server Error: /
Traceback (most recent call last):
  File "C:\Users\User\AppData\Roaming\Python\Python313\site-packages\django\db\backends\base\base.py", line 289, in ensure_connection
    self.connect()
    ~~~~~~~~~~~~^^
  File "C:\Users\User\AppData\Roaming\Python\Python313\site-packages\django\utils\asyncio.py", line 26, in inner
    return func(*args, **kwargs)
  File "C:\Users\User\AppData\Roaming\Python\Python313\site-packages\django\db\backends\base\base.py", line 270, in connect
    self.connection = self.get_new_connection(conn_params)
                      ~~~~~~~~~~~~~~~~~~~~~~~^^^^^^^^^^^^^
  File "C:\Users\User\AppData\Roaming\Python\Python313\site-packages\mssql\base.py", line 368, in get_new_connection
    conn = Database.connect(connstr, **args)
pyodbc.InterfaceError: ('28000', '[28000] [Microsoft][ODBC Driver 17 for SQL Server][SQL Server]Login failed for user \'SFPL_Connect\'. (18456) (SQLDriverConnect); [28000] [Microsoft][ODBC Driver 17 for SQL Server][SQL Server]Cannot open database "HR" requested by the login. The login failed. (4060); [28000] [Microsoft][ODBC Driver 17 for SQL Server]Invalid connection string attribute (0); [28000] [Microsoft][ODBC Driver 17 for SQL Server][SQL Server]Login failed for user \'SFPL_Connect\'. (18456); [28000] [Microsoft][ODBC Driver 17 for SQL Server][SQL Server]Cannot open database "HR" requested by the login. The login failed. (4060); [28000] [Microsoft][ODBC Driver 17 for SQL Server]Invalid connection string attribute (0)')

The above exception was the direct cause of the following exception:

Traceback (most recent call last):
  File "C:\Users\User\AppData\Roaming\Python\Python313\site-packages\django\core\handlers\exception.py", line 55, in inner
    response = get_response(request)
  File "C:\Users\User\AppData\Roaming\Python\Python313\site-packages\django\core\handlers\base.py", line 197, in _get_response
    response = wrapped_callback(request, *callback_args, **callback_kwargs)
  File "C:\Users\User\Desktop\Dev_Cyber_Quiz\Cyber-Security-Awareness-Quiz\Quiz\views.py", line 41, in home
    with connections['second_db'].cursor() as cursor:
         ~~~~~~~~~~~~~~~~~~~~~~~~~~~~~~~^^
  File "C:\Users\User\AppData\Roaming\Python\Python313\site-packages\django\utils\asyncio.py", line 26, in inner
    return func(*args, **kwargs)
  File "C:\Users\User\AppData\Roaming\Python\Python313\site-packages\django\db\backends\base\base.py", line 330, in cursor
    return self._cursor()
           ~~~~~~~~~~~~^^
  File "C:\Users\User\AppData\Roaming\Python\Python313\site-packages\mssql\base.py", line 261, in _cursor
    conn = super()._cursor()
  File "C:\Users\User\AppData\Roaming\Python\Python313\site-packages\django\db\backends\base\base.py", line 306, in _cursor
    self.ensure_connection()
    ~~~~~~~~~~~~~~~~~~~~~~^^
  File "C:\Users\User\AppData\Roaming\Python\Python313\site-packages\django\utils\asyncio.py", line 26, in inner
    return func(*args, **kwargs)
  File "C:\Users\User\AppData\Roaming\Python\Python313\site-packages\django\db\backends\base\base.py", line 288, in ensure_connection
    with self.wrap_database_errors:
         ^^^^^^^^^^^^^^^^^^^^^^^^^
  File "C:\Users\User\AppData\Roaming\Python\Python313\site-packages\django\db\utils.py", line 91, in __exit__
    raise dj_exc_value.with_traceback(traceback) from exc_value
  File "C:\Users\User\AppData\Roaming\Python\Python313\site-packages\django\db\backends\base\base.py", line 289, in ensure_connection
    self.connect()
    ~~~~~~~~~~~~^^
  File "C:\Users\User\AppData\Roaming\Python\Python313\site-packages\django\utils\asyncio.py", line 26, in inner
    return func(*args, **kwargs)
  File "C:\Users\User\AppData\Roaming\Python\Python313\site-packages\django\db\backends\base\base.py", line 270, in connect
    self.connection = self.get_new_connection(conn_params)
                      ~~~~~~~~~~~~~~~~~~~~~~~^^^^^^^^^^^^^
  File "C:\Users\User\AppData\Roaming\Python\Python313\site-packages\mssql\base.py", line 368, in get_new_connection
    conn = Database.connect(connstr, **args)
django.db.utils.InterfaceError: ('28000', '[28000] [Microsoft][ODBC Driver 17 for SQL Server][SQL Server]Login failed for user \'SFPL_Connect\'. (18456) (SQLDriverConnect); [28000] [Microsoft][ODBC Driver 17 for SQL Server][SQL Server]Cannot open database "HR" requested by the login. The login failed. (4060); [28000] [Microsoft][ODBC Driver 17 for SQL Server]Invalid connection string attribute (0); [28000] [Microsoft][ODBC Driver 17 for SQL Server][SQL Server]Login failed for user \'SFPL_Connect\'. (18456); [28000] [Microsoft][ODBC Driver 17 for SQL Server][SQL Server]Cannot open database "HR" requested by the login. The login failed. (4060); [28000] [Microsoft][ODBC Driver 17 for SQL Server]Invalid connection string attribute (0)')
"POST / HTTP/1.1" 500 149972
Internal Server Error: /download-excel-reports/
"GET /download-excel-reports/?type=reject&start=2025-04-10&end=2025-04-24 HTTP/1.1" 500 421
Internal Server Error: /download-excel-reports/
"GET /download-excel-reports/?type=reject&start=2025-04-10&end=2025-04-24 HTTP/1.1" 500 421
Internal Server Error: /download-excel-reports/
"GET /download-excel-reports/?type=reject&start=2025-04-10&end=2025-04-24 HTTP/1.1" 500 421
Internal Server Error: /download-excel-reports/
"GET /download-excel-reports/?type=completed&start=2025-04-10&end=2025-04-24 HTTP/1.1" 500 53
Internal Server Error: /download-excel-reports/
"GET /download-excel-reports/?type=reject&start=2025-04-10&end=2025-04-24 HTTP/1.1" 500 421
Internal Server Error: /download-excel-reports/
"GET /download-excel-reports/?type=reject&start=2025-04-10&end=2025-04-24 HTTP/1.1" 500 421
Internal Server Error: /download-excel-reports/
"GET /download-excel-reports/?type=reject&start=2025-04-10&end=2025-04-24 HTTP/1.1" 500 421
Internal Server Error: /download-excel-reports/
"GET /download-excel-reports/?type=reject&start=2025-04-10&end=2025-04-25 HTTP/1.1" 500 421
Internal Server Error: /download-excel-reports/
"GET /download-excel-reports/?type=reject&start=2025-04-10&end=2025-04-25 HTTP/1.1" 500 421
Internal Server Error: /download-excel-reports/
"GET /download-excel-reports/?type=reject&start=2025-04-10&end=2025-04-24 HTTP/1.1" 500 421
Internal Server Error: /download-excel-reports/
"GET /download-excel-reports/?type=reject&start=2025-04-10&end=2025-04-25 HTTP/1.1" 500 421
Internal Server Error: /download-excel-reports/
"GET /download-excel-reports/?type=reject&start=2025-04-10&end=2025-04-25 HTTP/1.1" 500 421
Internal Server Error: /download-excel-reports/
"GET /download-excel-reports/?type=reject&start=2025-04-10&end=2025-04-25 HTTP/1.1" 500 421
Internal Server Error: /download-excel-reports/
"GET /download-excel-reports/?type=reject&start=2025-04-10&end=2025-04-25 HTTP/1.1" 500 421
Internal Server Error: /download-excel-reports/
"GET /download-excel-reports/?type=reject&start=2025-04-10&end=2025-04-25 HTTP/1.1" 500 421
Internal Server Error: /download-excel-reports/
"GET /download-excel-reports/?type=reject&start=2025-04-10&end=2025-04-25 HTTP/1.1" 500 421
Internal Server Error: /download-excel-reports/
"GET /download-excel-reports/?type=reject&start=2025-04-10&end=2025-04-25 HTTP/1.1" 500 421
Internal Server Error: /download-excel-reports/
"GET /download-excel-reports/?type=reject&start=2025-04-10&end=2025-04-25 HTTP/1.1" 500 421
Internal Server Error: /download-excel-reports/
"GET /download-excel-reports/?type=reject&start=2025-04-10&end=2025-04-25 HTTP/1.1" 500 59
Internal Server Error: /download-excel-reports/
"GET /download-excel-reports/?type=reject&start=2025-04-10&end=2025-04-25 HTTP/1.1" 500 517
Internal Server Error: /download-excel-reports/
"GET /download-excel-reports/?type=reject&start=2025-04-10&end=2025-04-25 HTTP/1.1" 500 59
Internal Server Error: /
Traceback (most recent call last):
  File "C:\Users\User\AppData\Roaming\Python\Python313\site-packages\django\db\backends\base\base.py", line 289, in ensure_connection
    self.connect()
    ~~~~~~~~~~~~^^
  File "C:\Users\User\AppData\Roaming\Python\Python313\site-packages\django\utils\asyncio.py", line 26, in inner
    return func(*args, **kwargs)
  File "C:\Users\User\AppData\Roaming\Python\Python313\site-packages\django\db\backends\base\base.py", line 270, in connect
    self.connection = self.get_new_connection(conn_params)
                      ~~~~~~~~~~~~~~~~~~~~~~~^^^^^^^^^^^^^
  File "C:\Users\User\AppData\Roaming\Python\Python313\site-packages\mssql\base.py", line 368, in get_new_connection
    conn = Database.connect(connstr, **args)
pyodbc.InterfaceError: ('28000', '[28000] [Microsoft][ODBC Driver 17 for SQL Server][SQL Server]Login failed for user \'SFPL_Connect\'. (18456) (SQLDriverConnect); [28000] [Microsoft][ODBC Driver 17 for SQL Server][SQL Server]Cannot open database "HR" requested by the login. The login failed. (4060); [28000] [Microsoft][ODBC Driver 17 for SQL Server]Invalid connection string attribute (0); [28000] [Microsoft][ODBC Driver 17 for SQL Server][SQL Server]Login failed for user \'SFPL_Connect\'. (18456); [28000] [Microsoft][ODBC Driver 17 for SQL Server][SQL Server]Cannot open database "HR" requested by the login. The login failed. (4060); [28000] [Microsoft][ODBC Driver 17 for SQL Server]Invalid connection string attribute (0)')

The above exception was the direct cause of the following exception:

Traceback (most recent call last):
  File "C:\Users\User\AppData\Roaming\Python\Python313\site-packages\django\core\handlers\exception.py", line 55, in inner
    response = get_response(request)
  File "C:\Users\User\AppData\Roaming\Python\Python313\site-packages\django\core\handlers\base.py", line 197, in _get_response
    response = wrapped_callback(request, *callback_args, **callback_kwargs)
  File "C:\Users\User\Desktop\Dev_Cyber_Quiz\Cyber-Security-Awareness-Quiz\Quiz\views.py", line 41, in home
    with connections['second_db'].cursor() as cursor:
         ~~~~~~~~~~~~~~~~~~~~~~~~~~~~~~~^^
  File "C:\Users\User\AppData\Roaming\Python\Python313\site-packages\django\utils\asyncio.py", line 26, in inner
    return func(*args, **kwargs)
  File "C:\Users\User\AppData\Roaming\Python\Python313\site-packages\django\db\backends\base\base.py", line 330, in cursor
    return self._cursor()
           ~~~~~~~~~~~~^^
  File "C:\Users\User\AppData\Roaming\Python\Python313\site-packages\mssql\base.py", line 261, in _cursor
    conn = super()._cursor()
  File "C:\Users\User\AppData\Roaming\Python\Python313\site-packages\django\db\backends\base\base.py", line 306, in _cursor
    self.ensure_connection()
    ~~~~~~~~~~~~~~~~~~~~~~^^
  File "C:\Users\User\AppData\Roaming\Python\Python313\site-packages\django\utils\asyncio.py", line 26, in inner
    return func(*args, **kwargs)
  File "C:\Users\User\AppData\Roaming\Python\Python313\site-packages\django\db\backends\base\base.py", line 288, in ensure_connection
    with self.wrap_database_errors:
         ^^^^^^^^^^^^^^^^^^^^^^^^^
  File "C:\Users\User\AppData\Roaming\Python\Python313\site-packages\django\db\utils.py", line 91, in __exit__
    raise dj_exc_value.with_traceback(traceback) from exc_value
  File "C:\Users\User\AppData\Roaming\Python\Python313\site-packages\django\db\backends\base\base.py", line 289, in ensure_connection
    self.connect()
    ~~~~~~~~~~~~^^
  File "C:\Users\User\AppData\Roaming\Python\Python313\site-packages\django\utils\asyncio.py", line 26, in inner
    return func(*args, **kwargs)
  File "C:\Users\User\AppData\Roaming\Python\Python313\site-packages\django\db\backends\base\base.py", line 270, in connect
    self.connection = self.get_new_connection(conn_params)
                      ~~~~~~~~~~~~~~~~~~~~~~~^^^^^^^^^^^^^
  File "C:\Users\User\AppData\Roaming\Python\Python313\site-packages\mssql\base.py", line 368, in get_new_connection
    conn = Database.connect(connstr, **args)
django.db.utils.InterfaceError: ('28000', '[28000] [Microsoft][ODBC Driver 17 for SQL Server][SQL Server]Login failed for user \'SFPL_Connect\'. (18456) (SQLDriverConnect); [28000] [Microsoft][ODBC Driver 17 for SQL Server][SQL Server]Cannot open database "HR" requested by the login. The login failed. (4060); [28000] [Microsoft][ODBC Driver 17 for SQL Server]Invalid connection string attribute (0); [28000] [Microsoft][ODBC Driver 17 for SQL Server][SQL Server]Login failed for user \'SFPL_Connect\'. (18456); [28000] [Microsoft][ODBC Driver 17 for SQL Server][SQL Server]Cannot open database "HR" requested by the login. The login failed. (4060); [28000] [Microsoft][ODBC Driver 17 for SQL Server]Invalid connection string attribute (0)')
"POST / HTTP/1.1" 500 150245
